Workbook
Name Slicer_Departamento: #N/A
Name Slicer_Empresa: #N/A
Name Slicer_Responsável: #N/A
Name Slicer_Tipo: #N/A
Name Slicer_Unidade: #N/A

Sheet Centro de Custo
A11: Empresa | B11: Unidade | C11: Tipo | D11: Área | E11: Departamento | F11: CENTRO DE CUSTO | G11: Responsável
A12: Martini Meat | B12: Paranaguá | C12: Carga Geral | D12: Operação | E12: TI | F12: CG-PNG | TI | G12: Alexandre Ayabe
A13: Martini Meat | B13: Paranaguá | C13: Frigorífico | D13: Operação | E13: TI | F13: FG-PNG | TI | G13: Alexandre Ayabe
A14: Martini Meat | B14: Paranaguá | C14: Pátio | D14: Operação | E14: TI | F14: PT-PNG | TI | G14: Alexandre Ayabe
A15: Martini Meat | B15: Paranaguá | C15: RATEIO Unidade | D15: Operação | E15: TI | F15: PNG | TI | G15: Alexandre Ayabe
A16: Martini Meat | B16: Rio Grande | C16: Frigorífico | D16: Operação | E16: TI | F16: FG-RGD | TI | G16: Alexandre Ayabe
A17: Martini Meat | B17: Rio Grande | C17: Pátio | D17: Operação | E17: TI | F17: PT-RGD | TI | G17: Alexandre Ayabe
A18: Martini Meat | B18: Rio Grande | C18: RATEIO Unidade | D18: Operação | E18: TI | F18: RGD | TI | G18: Alexandre Ayabe
A19: Martini Meat | B19: Ponta Grossa | C19: Carga Geral | D19: Operação | E19: TI | F19: CG-PTG | TI | G19: Alexandre Ayabe
A20: Martini Meat | B20: Itajaí | C20: Frigorífico | D20: Operação | E20: TI | F20: FG-ITJ | TI | G20: Alexandre Ayabe
A21: Martini Meat | B21: Itajaí | C21: Pátio | D21: Operação | E21: TI | F21: PT-ITJ | TI | G21: Alexandre Ayabe
A22: Martini Meat | B22: Itajaí | C22: RATEIO Unidade | D22: Operação | E22: TI | F22: ITJ | TI | G22: Alexandre Ayabe
... A31: Cone Sul | B31: Plataforma | C31: G&A | D31: PL | E31: TI | F31: PL | TI | G31: Alexandre Ayabe

Sheet Budget
E1: Orçamento | F1: 2026 | AQ1: =SUM(AQ$5:AQ$328) -> 16192.876 | BE1: =SUM(BE$5:BE$352) -> 16739.988 | BS1: =SUM(BS$5:BT$352) -> 2846.9367
E2: Responsável | F2: Alexandre Ayabe
AE3: BRL'000 (sem Inflação) | AS3: BRL'000 | BG3: USD'000
A4: Cenário | B4: Ano | C4: Empresa | D4: Unidade | E4: Tipo | F4: Fornecedor | G4: Descrição Global | H4: Descrição | I4: Categoría | J4: Recorrência | K4: Prioridade | L4: Descr Centro de custo | M4: Responsável | N4: Despesa [ KPI ] | O4: Mes de reajuste (inflação) | P4: Moeda | Q4: 46023 | R4: =EDATE(Q4,1) -> 46054 | S4: =EDATE(R4,1) -> 46082 | T4: =EDATE(S4,1) -> 46113 | U4: =EDATE(T4,1) -> 46143 | V4: =EDATE(U4,1) -> 46174 | W4: =EDATE(V4,1) -> 46204 | X4: =EDATE(W4,1) -> 46235 | Y4: =EDATE(X4,1) -> 46266 | ... AB4: =EDATE(AA4,1) -> 46357 | AC4: BG.2026 | AD4: - | AE4: 46023 | AF4: =EDATE(AE4,1) -> 46054 | AG4: =EDATE(AF4,1) -> 46082 | AH4: =EDATE(AG4,1) -> 46113 | AI4: =EDATE(AH4,1) -> 46143 | AJ4: =EDATE(AI4,1) -> 46174 | AK4: =EDATE(AJ4,1) -> 46204 | AL4: =EDATE(AK4,1) -> 46235 | AM4: =EDATE(AL4,1) -> 46266 | ... AP4: =EDATE(AO4,1) -> 46357 | AQ4: BG.2026 | AR4: - | AS4: 46023 | AT4: =EDATE(AS4,1) -> 46054 | AU4: =EDATE(AT4,1) -> 46082 | AV4: =EDATE(AU4,1) -> 46113 | AW4: =EDATE(AV4,1) -> 46143 | AX4: =EDATE(AW4,1) -> 46174 | AY4: =EDATE(AX4,1) -> 46204 | AZ4: =EDATE(AY4,1) -> 46235 | BA4: =EDATE(AZ4,1) -> 46266 | ... BD4: =EDATE(BC4,1) -> 46357 | BE4: BG.2026 | BF4: - | BG4: 46023 | BH4: =EDATE(BG4,1) -> 46054 | BI4: =EDATE(BH4,1) -> 46082 | BJ4: =EDATE(BI4,1) -> 46113 | BK4: =EDATE(BJ4,1) -> 46143 | BL4: =EDATE(BK4,1) -> 46174 | BM4: =EDATE(BL4,1) -> 46204 | BN4: =EDATE(BM4,1) -> 46235 | BO4: =EDATE(BN4,1) -> 46266 | ... BR4: =EDATE(BQ4,1) -> 46357 | BS4: BG.2026 | BT4: DRE [ KPI ]
A5: =IF(ISBLANK($F5),"","Budget") -> Budget | B5: =IF(ISBLANK($F5),"",$F$1) -> 2026 | C5: =IF(ISBLANK($L5),"",_xlfn.XLOOKUP($L5,'CENTRO CUSTO'!$A:$A,'CENTRO CUSTO'!F:F,FALSE,0)) -> Transporte | D5: =IF(ISBLANK($L5),"",_xlfn.XLOOKUP($L5,'CENTRO CUSTO'!$A:$A,'CENTRO CUSTO'!G:G,FALSE,0)) -> BU-TR | E5: =IF(ISBLANK($L5),"",_xlfn.XLOOKUP($L5,'CENTRO CUSTO'!$A:$A,'CENTRO CUSTO'!H:H,FALSE,0)) -> G&A | F5: SPRO | G5: Applications support and maintenance | H5: SAP R3 - Licença | I5: Existente | J5: Mensal | K5: Contrato em Curso | L5: BU-MMTR | TI | M5: =IF(ISBLANK($L5),"",_xlfn.XLOOKUP($L5,'CENTRO CUSTO'!$A:$A,'CENTRO CUSTO'!D:D,FALSE,0)) -> Alexandre Ayabe | N5: Licença SAP | O5: 46023 | P5: BRL | Q5: =650000*Rateio!$E$3/12 -> 0 | R5: =650000*Rateio!$E$3/12 -> 0 | S5: =650000*Rateio!$E$3/12 -> 0 | T5: =650000*Rateio!$E$3/12 -> 0 | U5: =650000*Rateio!$E$3/12 -> 0 | V5: =650000*Rateio!$E$3/12 -> 0 | W5: =650000*Rateio!$E$3/12 -> 0 | X5: =650000*Rateio!$E$3/12 -> 0 | ... AB5: =650000*Rateio!$E$3/12 -> 0 | AC5: =IF(AND(ISBLANK($Q5),ISBLANK($R5),ISBLANK($S5),ISBLANK($T5),ISBLANK($U5),ISBLANK($V5),ISBLANK($W5),ISBLANK($X5),ISBLANK($Y5),ISBLANK($Z5),ISBLANK($AA5),ISBLANK($AB5)),"",SUM(Q5:AB5)) -> 0 | AE5: =IF(ISBLANK(Q5),"",IF($P5="BRL",Q5,Q5*Macroindicadores!B$2)/1000) -> 0 | AF5: =IF(ISBLANK(R5),"",IF($P5="BRL",R5,R5*Macroindicadores!C$2)/1000) -> 0 | AG5: =IF(ISBLANK(S5),"",IF($P5="BRL",S5,S5*Macroindicadores!D$2)/1000) -> 0 | AH5: =IF(ISBLANK(T5),"",IF($P5="BRL",T5,T5*Macroindicadores!E$2)/1000) -> 0 | AI5: =IF(ISBLANK(U5),"",IF($P5="BRL",U5,U5*Macroindicadores!F$2)/1000) -> 0 | AJ5: =IF(ISBLANK(V5),"",IF($P5="BRL",V5,V5*Macroindicadores!G$2)/1000) -> 0 | AK5: =IF(ISBLANK(W5),"",IF($P5="BRL",W5,W5*Macroindicadores!H$2)/1000) -> 0 | AL5: =IF(ISBLANK(X5),"",IF($P5="BRL",X5,X5*Macroindicadores!I$2)/1000) -> 0 | ... AP5: =IF(ISBLANK(AB5),"",IF($P5="BRL",AB5,AB5*Macroindicadores!M$2)/1000) -> 0 | AQ5: =IF(AND(ISBLANK(AE5),ISBLANK(AF5),ISBLANK(AG5),ISBLANK(AH5),ISBLANK(AI5),ISBLANK(AJ5),ISBLANK(AK5),ISBLANK(AL5),ISBLANK(AM5),ISBLANK(AN5),ISBLANK(AO5),ISBLANK(AP5)),"",SUM(AE5:AP5)) -> 0 | AS5: =IF(ISBLANK(Q5),"",IF(ISBLANK($O5),AE5,IF($J5="ANUAL",AE5*(1+Macroindicadores!B$7),IF(AND($I5="NOVO",MONTH($O5)=MONTH(AS$4)),AE5*(1+Macroindicadores!B$7),IF(AND($J5="PONTUAL",MONTH($O5)=MONTH(AS$4)),AE5*(1+Macroindicadores!B$7),IF(AND($J5="PONTUAL",MONTH($O5)<MONTH(AS$4)),MIN(AR5:$AS5),IF(AND($I5="NOVO",MONTH($O5)>MONTH(AS$4)),AE5,IF(MONTH($O5)>MONTH(AS$4),AE5,IF(MONTH($O5)=MONTH(AS$4),AE5*(1+Macroindicadores!B$7),AR5))))))))) -> 0 | AT5: =IF(ISBLANK(R5),"",IF(ISBLANK($O5),AF5,IF($J5="ANUAL",AF5*(1+Macroindicadores!C$7),IF(AND($I5="NOVO",MONTH($O5)=MONTH(AT$4)),AF5*(1+Macroindicadores!C$7),IF(AND($J5="PONTUAL",MONTH($O5)=MONTH(AT$4)),AF5*(1+Macroindicadores!C$7),IF(AND($J5="PONTUAL",MONTH($O5)<MONTH(AT$4)),MIN($AS5:AS5),IF(AND($I5="NOVO",MONTH($O5)>MONTH(AT$4)),AF5,IF(MONTH($O5)>MONTH(AT$4),AF5,IF(MONTH($O5)=MONTH(AT$4),AF5*(1+Macroindicadores!C$7),AS5))))))))) -> 0 | AU5: =IF(ISBLANK(S5),"",IF(ISBLANK($O5),AG5,IF($J5="ANUAL",AG5*(1+Macroindicadores!D$7),IF(AND($I5="NOVO",MONTH($O5)=MONTH(AU$4)),AG5*(1+Macroindicadores!D$7),IF(AND($J5="PONTUAL",MONTH($O5)=MONTH(AU$4)),AG5*(1+Macroindicadores!D$7),IF(AND($J5="PONTUAL",MONTH($O5)<MONTH(AU$4)),MIN($AS5:AT5),IF(AND($I5="NOVO",MONTH($O5)>MONTH(AU$4)),AG5,IF(MONTH($O5)>MONTH(AU$4),AG5,IF(MONTH($O5)=MONTH(AU$4),AG5*(1+Macroindicadores!D$7),AT5))))))))) -> 0 | AV5: =IF(ISBLANK(T5),"",IF(ISBLANK($O5),AH5,IF($J5="ANUAL",AH5*(1+Macroindicadores!E$7),IF(AND($I5="NOVO",MONTH($O5)=MONTH(AV$4)),AH5*(1+Macroindicadores!E$7),IF(AND($J5="PONTUAL",MONTH($O5)=MONTH(AV$4)),AH5*(1+Macroindicadores!E$7),IF(AND($J5="PONTUAL",MONTH($O5)<MONTH(AV$4)),MIN($AS5:AU5),IF(AND($I5="NOVO",MONTH($O5)>MONTH(AV$4)),AH5,IF(MONTH($O5)>MONTH(AV$4),AH5,IF(MONTH($O5)=MONTH(AV$4),AH5*(1+Macroindicadores!E$7),AU5))))))))) -> 0 | AW5: =IF(ISBLANK(U5),"",IF(ISBLANK($O5),AI5,IF($J5="ANUAL",AI5*(1+Macroindicadores!F$7),IF(AND($I5="NOVO",MONTH($O5)=MONTH(AW$4)),AI5*(1+Macroindicadores!F$7),IF(AND($J5="PONTUAL",MONTH($O5)=MONTH(AW$4)),AI5*(1+Macroindicadores!F$7),IF(AND($J5="PONTUAL",MONTH($O5)<MONTH(AW$4)),MIN($AS5:AV5),IF(AND($I5="NOVO",MONTH($O5)>MONTH(AW$4)),AI5,IF(MONTH($O5)>MONTH(AW$4),AI5,IF(MONTH($O5)=MONTH(AW$4),AI5*(1+Macroindicadores!F$7),AV5))))))))) -> 0 | AX5: =IF(ISBLANK(V5),"",IF(ISBLANK($O5),AJ5,IF($J5="ANUAL",AJ5*(1+Macroindicadores!G$7),IF(AND($I5="NOVO",MONTH($O5)=MONTH(AX$4)),AJ5*(1+Macroindicadores!G$7),IF(AND($J5="PONTUAL",MONTH($O5)=MONTH(AX$4)),AJ5*(1+Macroindicadores!G$7),IF(AND($J5="PONTUAL",MONTH($O5)<MONTH(AX$4)),MIN($AS5:AW5),IF(AND($I5="NOVO",MONTH($O5)>MONTH(AX$4)),AJ5,IF(MONTH($O5)>MONTH(AX$4),AJ5,IF(MONTH($O5)=MONTH(AX$4),AJ5*(1+Macroindicadores!G$7),AW5))))))))) -> 0 | AY5: =IF(ISBLANK(W5),"",IF(ISBLANK($O5),AK5,IF($J5="ANUAL",AK5*(1+Macroindicadores!H$7),IF(AND($I5="NOVO",MONTH($O5)=MONTH(AY$4)),AK5*(1+Macroindicadores!H$7),IF(AND($J5="PONTUAL",MONTH($O5)=MONTH(AY$4)),AK5*(1+Macroindicadores!H$7),IF(AND($J5="PONTUAL",MONTH($O5)<MONTH(AY$4)),MIN($AS5:AX5),IF(AND($I5="NOVO",MONTH($O5)>MONTH(AY$4)),AK5,IF(MONTH($O5)>MONTH(AY$4),AK5,IF(MONTH($O5)=MONTH(AY$4),AK5*(1+Macroindicadores!H$7),AX5))))))))) -> 0 | AZ5: =IF(ISBLANK(X5),"",IF(ISBLANK($O5),AL5,IF($J5="ANUAL",AL5*(1+Macroindicadores!I$7),IF(AND($I5="NOVO",MONTH($O5)=MONTH(AZ$4)),AL5*(1+Macroindicadores!I$7),IF(AND($J5="PONTUAL",MONTH($O5)=MONTH(AZ$4)),AL5*(1+Macroindicadores!I$7),IF(AND($J5="PONTUAL",MONTH($O5)<MONTH(AZ$4)),MIN($AS5:AY5),IF(AND($I5="NOVO",MONTH($O5)>MONTH(AZ$4)),AL5,IF(MONTH($O5)>MONTH(AZ$4),AL5,IF(MONTH($O5)=MONTH(AZ$4),AL5*(1+Macroindicadores!I$7),AY5))))))))) -> 0 | BA5: =IF(ISBLANK(Y5),"",IF(ISBLANK($O5),AM5,IF($J5="ANUAL",AM5*(1+Macroindicadores!J$7),IF(AND($I5="NOVO",MONTH($O5)=MONTH(BA$4)),AM5*(1+Macroindicadores!J$7),IF(AND($J5="PONTUAL",MONTH($O5)=MONTH(BA$4)),AM5*(1+Macroindicadores!J$7),IF(AND($J5="PONTUAL",MONTH($O5)<MONTH(BA$4)),MIN($AS5:AZ5),IF(AND($I5="NOVO",MONTH($O5)>MONTH(BA$4)),AM5,IF(MONTH($O5)>MONTH(BA$4),AM5,IF(MONTH($O5)=MONTH(BA$4),AM5*(1+Macroindicadores!J$7),AZ5))))))))) -> 0 | ... BD5: =IF(ISBLANK(AB5),"",IF(ISBLANK($O5),AP5,IF($J5="ANUAL",AP5*(1+Macroindicadores!M$7),IF(AND($I5="NOVO",MONTH($O5)=MONTH(BD$4)),AP5*(1+Macroindicadores!M$7),IF(AND($J5="PONTUAL",MONTH($O5)=MONTH(BD$4)),AP5*(1+Macroindicadores!M$7),IF(AND($J5="PONTUAL",MONTH($O5)<MONTH(BD$4)),MIN($AS5:BC5),IF(AND($I5="NOVO",MONTH($O5)>MONTH(BD$4)),AP5,IF(MONTH($O5)>MONTH(BD$4),AP5,IF(MONTH($O5)=MONTH(BD$4),AP5*(1+Macroindicadores!M$7),BC5))))))))) -> 0 | BE5: =IF(AND(ISBLANK($Q5),ISBLANK($R5),ISBLANK($S5),ISBLANK($T5),ISBLANK($U5),ISBLANK($V5),ISBLANK($W5),ISBLANK($X5),ISBLANK($Y5),ISBLANK($Z5),ISBLANK($AA5),ISBLANK($AB5)),"",SUM(AS5:BD5)) -> 0 | BG5: =IF(ISBLANK(Q5),"",AS5/Macroindicadores!B$2) -> 0 | BH5: =IF(ISBLANK(R5),"",AT5/Macroindicadores!C$2) -> 0 | BI5: =IF(ISBLANK(S5),"",AU5/Macroindicadores!D$2) -> 0 | BJ5: =IF(ISBLANK(T5),"",AV5/Macroindicadores!E$2) -> 0 | BK5: =IF(ISBLANK(U5),"",AW5/Macroindicadores!F$2) -> 0 | BL5: =IF(ISBLANK(V5),"",AX5/Macroindicadores!G$2) -> 0 | BM5: =IF(ISBLANK(W5),"",AY5/Macroindicadores!H$2) -> 0 | BN5: =IF(ISBLANK(X5),"",AZ5/Macroindicadores!I$2) -> 0 | ... BR5: =IF(ISBLANK(AB5),"",BD5/Macroindicadores!M$2) -> 0 | BS5: =IF(AND(ISBLANK($Q5),ISBLANK($R5),ISBLANK($S5),ISBLANK($T5),ISBLANK($U5),ISBLANK($V5),ISBLANK($W5),ISBLANK($X5),ISBLANK($Y5),ISBLANK($Z5),ISBLANK($AA5),ISBLANK($AB5)),"",SUM(BG5:BR5)) -> 0 | BT5: =IF(ISBLANK($L5),"",_xlfn.XLOOKUP($L5,'CENTRO CUSTO'!$A:$A,'CENTRO CUSTO'!$E:$E,FALSE,0)) -> G&A BU
A6: =IF(ISBLANK($F6),"","Budget") -> Budget | B6: =IF(ISBLANK($F6),"",$F$1) -> 2026 | C6: =IF(ISBLANK($L6),"",_xlfn.XLOOKUP($L6,'CENTRO CUSTO'!$A:$A,'CENTRO CUSTO'!F:F,FALSE,0)) -> Martini Meat | D6: =IF(ISBLANK($L6),"",_xlfn.XLOOKUP($L6,'CENTRO CUSTO'!$A:$A,'CENTRO CUSTO'!G:G,FALSE,0)) -> BU-MMAZ | E6: =IF(ISBLANK($L6),"",_xlfn.XLOOKUP($L6,'CENTRO CUSTO'!$A:$A,'CENTRO CUSTO'!H:H,FALSE,0)) -> G&A | F6: SPRO | G6: Applications support and maintenance | H6: SAP R3 - Licença | I6: Existente | J6: Mensal | K6: Contrato em Curso | L6: BU-MMAZ | TI | M6: =IF(ISBLANK($L6),"",_xlfn.XLOOKUP($L6,'CENTRO CUSTO'!$A:$A,'CENTRO CUSTO'!D:D,FALSE,0)) -> Alexandre Ayabe | N6: Licença SAP | O6: 46023 | P6: BRL | Q6: =650000*Rateio!$E$4/12 -> 54166.667 | R6: =650000*Rateio!$E$4/12 -> 54166.667 | S6: =650000*Rateio!$E$4/12 -> 54166.667 | T6: =650000*Rateio!$E$4/12 -> 54166.667 | U6: =650000*Rateio!$E$4/12 -> 54166.667 | V6: =650000*Rateio!$E$4/12 -> 54166.667 | W6: =650000*Rateio!$E$4/12 -> 54166.667 | X6: =650000*Rateio!$E$4/12 -> 54166.667 | ... AB6: =650000*Rateio!$E$4/12 -> 54166.667 | AC6: =IF(AND(ISBLANK($Q6),ISBLANK($R6),ISBLANK($S6),ISBLANK($T6),ISBLANK($U6),ISBLANK($V6),ISBLANK($W6),ISBLANK($X6),ISBLANK($Y6),ISBLANK($Z6),ISBLANK($AA6),ISBLANK($AB6)),"",SUM(Q6:AB6)) -> 650000 | AE6: =IF(ISBLANK(Q6),"",IF($P6="BRL",Q6,Q6*Macroindicadores!B$2)/1000) -> 54.166667 | AF6: =IF(ISBLANK(R6),"",IF($P6="BRL",R6,R6*Macroindicadores!C$2)/1000) -> 54.166667 | AG6: =IF(ISBLANK(S6),"",IF($P6="BRL",S6,S6*Macroindicadores!D$2)/1000) -> 54.166667 | AH6: =IF(ISBLANK(T6),"",IF($P6="BRL",T6,T6*Macroindicadores!E$2)/1000) -> 54.166667 | AI6: =IF(ISBLANK(U6),"",IF($P6="BRL",U6,U6*Macroindicadores!F$2)/1000) -> 54.166667 | AJ6: =IF(ISBLANK(V6),"",IF($P6="BRL",V6,V6*Macroindicadores!G$2)/1000) -> 54.166667 | AK6: =IF(ISBLANK(W6),"",IF($P6="BRL",W6,W6*Macroindicadores!H$2)/1000) -> 54.166667 | AL6: =IF(ISBLANK(X6),"",IF($P6="BRL",X6,X6*Macroindicadores!I$2)/1000) -> 54.166667 | ... AP6: =IF(ISBLANK(AB6),"",IF($P6="BRL",AB6,AB6*Macroindicadores!M$2)/1000) -> 54.166667 | AQ6: =IF(AND(ISBLANK($Q6),ISBLANK($R6),ISBLANK($S6),ISBLANK($T6),ISBLANK($U6),ISBLANK($V6),ISBLANK($W6),ISBLANK($X6),ISBLANK($Y6),ISBLANK($Z6),ISBLANK($AA6),ISBLANK($AB6)),"",SUM(AE6:AP6)) -> 650 | AS6: =IF(ISBLANK(Q6),"",IF(ISBLANK($O6),AE6,IF($J6="ANUAL",AE6*(1+Macroindicadores!B$7),IF(AND($I6="NOVO",MONTH($O6)=MONTH(AS$4)),AE6*(1+Macroindicadores!B$7),IF(AND($J6="PONTUAL",MONTH($O6)=MONTH(AS$4)),AE6*(1+Macroindicadores!B$7),IF(AND($J6="PONTUAL",MONTH($O6)<MONTH(AS$4)),MIN(AR6:$AS6),IF(AND($I6="NOVO",MONTH($O6)>MONTH(AS$4)),AE6,IF(MONTH($O6)>MONTH(AS$4),AE6,IF(MONTH($O6)=MONTH(AS$4),AE6*(1+Macroindicadores!B$7),AR6))))))))) -> 57.128233 | AT6: =IF(ISBLANK(R6),"",IF(ISBLANK($O6),AF6,IF($J6="ANUAL",AF6*(1+Macroindicadores!C$7),IF(AND($I6="NOVO",MONTH($O6)=MONTH(AT$4)),AF6*(1+Macroindicadores!C$7),IF(AND($J6="PONTUAL",MONTH($O6)=MONTH(AT$4)),AF6*(1+Macroindicadores!C$7),IF(AND($J6="PONTUAL",MONTH($O6)<MONTH(AT$4)),MIN($AS6:AS6),IF(AND($I6="NOVO",MONTH($O6)>MONTH(AT$4)),AF6,IF(MONTH($O6)>MONTH(AT$4),AF6,IF(MONTH($O6)=MONTH(AT$4),AF6*(1+Macroindicadores!C$7),AS6))))))))) -> 57.128233 | AU6: =IF(ISBLANK(S6),"",IF(ISBLANK($O6),AG6,IF($J6="ANUAL",AG6*(1+Macroindicadores!D$7),IF(AND($I6="NOVO",MONTH($O6)=MONTH(AU$4)),AG6*(1+Macroindicadores!D$7),IF(AND($J6="PONTUAL",MONTH($O6)=MONTH(AU$4)),AG6*(1+Macroindicadores!D$7),IF(AND($J6="PONTUAL",MONTH($O6)<MONTH(AU$4)),MIN($AS6:AT6),IF(AND($I6="NOVO",MONTH($O6)>MONTH(AU$4)),AG6,IF(MONTH($O6)>MONTH(AU$4),AG6,IF(MONTH($O6)=MONTH(AU$4),AG6*(1+Macroindicadores!D$7),AT6))))))))) -> 57.128233 | AV6: =IF(ISBLANK(T6),"",IF(ISBLANK($O6),AH6,IF($J6="ANUAL",AH6*(1+Macroindicadores!E$7),IF(AND($I6="NOVO",MONTH($O6)=MONTH(AV$4)),AH6*(1+Macroindicadores!E$7),IF(AND($J6="PONTUAL",MONTH($O6)=MONTH(AV$4)),AH6*(1+Macroindicadores!E$7),IF(AND($J6="PONTUAL",MONTH($O6)<MONTH(AV$4)),MIN($AS6:AU6),IF(AND($I6="NOVO",MONTH($O6)>MONTH(AV$4)),AH6,IF(MONTH($O6)>MONTH(AV$4),AH6,IF(MONTH($O6)=MONTH(AV$4),AH6*(1+Macroindicadores!E$7),AU6))))))))) -> 57.128233 | AW6: =IF(ISBLANK(U6),"",IF(ISBLANK($O6),AI6,IF($J6="ANUAL",AI6*(1+Macroindicadores!F$7),IF(AND($I6="NOVO",MONTH($O6)=MONTH(AW$4)),AI6*(1+Macroindicadores!F$7),IF(AND($J6="PONTUAL",MONTH($O6)=MONTH(AW$4)),AI6*(1+Macroindicadores!F$7),IF(AND($J6="PONTUAL",MONTH($O6)<MONTH(AW$4)),MIN($AS6:AV6),IF(AND($I6="NOVO",MONTH($O6)>MONTH(AW$4)),AI6,IF(MONTH($O6)>MONTH(AW$4),AI6,IF(MONTH($O6)=MONTH(AW$4),AI6*(1+Macroindicadores!F$7),AV6))))))))) -> 57.128233 | AX6: =IF(ISBLANK(V6),"",IF(ISBLANK($O6),AJ6,IF($J6="ANUAL",AJ6*(1+Macroindicadores!G$7),IF(AND($I6="NOVO",MONTH($O6)=MONTH(AX$4)),AJ6*(1+Macroindicadores!G$7),IF(AND($J6="PONTUAL",MONTH($O6)=MONTH(AX$4)),AJ6*(1+Macroindicadores!G$7),IF(AND($J6="PONTUAL",MONTH($O6)<MONTH(AX$4)),MIN($AS6:AW6),IF(AND($I6="NOVO",MONTH($O6)>MONTH(AX$4)),AJ6,IF(MONTH($O6)>MONTH(AX$4),AJ6,IF(MONTH($O6)=MONTH(AX$4),AJ6*(1+Macroindicadores!G$7),AW6))))))))) -> 57.128233 | AY6: =IF(ISBLANK(W6),"",IF(ISBLANK($O6),AK6,IF($J6="ANUAL",AK6*(1+Macroindicadores!H$7),IF(AND($I6="NOVO",MONTH($O6)=MONTH(AY$4)),AK6*(1+Macroindicadores!H$7),IF(AND($J6="PONTUAL",MONTH($O6)=MONTH(AY$4)),AK6*(1+Macroindicadores!H$7),IF(AND($J6="PONTUAL",MONTH($O6)<MONTH(AY$4)),MIN($AS6:AX6),IF(AND($I6="NOVO",MONTH($O6)>MONTH(AY$4)),AK6,IF(MONTH($O6)>MONTH(AY$4),AK6,IF(MONTH($O6)=MONTH(AY$4),AK6*(1+Macroindicadores!H$7),AX6))))))))) -> 57.128233 | AZ6: =IF(ISBLANK(X6),"",IF(ISBLANK($O6),AL6,IF($J6="ANUAL",AL6*(1+Macroindicadores!I$7),IF(AND($I6="NOVO",MONTH($O6)=MONTH(AZ$4)),AL6*(1+Macroindicadores!I$7),IF(AND($J6="PONTUAL",MONTH($O6)=MONTH(AZ$4)),AL6*(1+Macroindicadores!I$7),IF(AND($J6="PONTUAL",MONTH($O6)<MONTH(AZ$4)),MIN($AS6:AY6),IF(AND($I6="NOVO",MONTH($O6)>MONTH(AZ$4)),AL6,IF(MONTH($O6)>MONTH(AZ$4),AL6,IF(MONTH($O6)=MONTH(AZ$4),AL6*(1+Macroindicadores!I$7),AY6))))))))) -> 57.128233 | BA6: =IF(ISBLANK(Y6),"",IF(ISBLANK($O6),AM6,IF($J6="ANUAL",AM6*(1+Macroindicadores!J$7),IF(AND($I6="NOVO",MONTH($O6)=MONTH(BA$4)),AM6*(1+Macroindicadores!J$7),IF(AND($J6="PONTUAL",MONTH($O6)=MONTH(BA$4)),AM6*(1+Macroindicadores!J$7),IF(AND($J6="PONTUAL",MONTH($O6)<MONTH(BA$4)),MIN($AS6:AZ6),IF(AND($I6="NOVO",MONTH($O6)>MONTH(BA$4)),AM6,IF(MONTH($O6)>MONTH(BA$4),AM6,IF(MONTH($O6)=MONTH(BA$4),AM6*(1+Macroindicadores!J$7),AZ6))))))))) -> 57.128233 | ... BD6: =IF(ISBLANK(AB6),"",IF(ISBLANK($O6),AP6,IF($J6="ANUAL",AP6*(1+Macroindicadores!M$7),IF(AND($I6="NOVO",MONTH($O6)=MONTH(BD$4)),AP6*(1+Macroindicadores!M$7),IF(AND($J6="PONTUAL",MONTH($O6)=MONTH(BD$4)),AP6*(1+Macroindicadores!M$7),IF(AND($J6="PONTUAL",MONTH($O6)<MONTH(BD$4)),MIN($AS6:BC6),IF(AND($I6="NOVO",MONTH($O6)>MONTH(BD$4)),AP6,IF(MONTH($O6)>MONTH(BD$4),AP6,IF(MONTH($O6)=MONTH(BD$4),AP6*(1+Macroindicadores!M$7),BC6))))))))) -> 57.128233 | BE6: =IF(AND(ISBLANK($Q6),ISBLANK($R6),ISBLANK($S6),ISBLANK($T6),ISBLANK($U6),ISBLANK($V6),ISBLANK($W6),ISBLANK($X6),ISBLANK($Y6),ISBLANK($Z6),ISBLANK($AA6),ISBLANK($AB6)),"",SUM(AS6:BD6)) -> 685.5388 | BG6: =IF(ISBLANK(Q6),"",AS6/Macroindicadores!B$2) -> 9.715686 | BH6: =IF(ISBLANK(R6),"",AT6/Macroindicadores!C$2) -> 9.715686 | BI6: =IF(ISBLANK(S6),"",AU6/Macroindicadores!D$2) -> 9.715686 | BJ6: =IF(ISBLANK(T6),"",AV6/Macroindicadores!E$2) -> 9.715686 | BK6: =IF(ISBLANK(U6),"",AW6/Macroindicadores!F$2) -> 9.715686 | BL6: =IF(ISBLANK(V6),"",AX6/Macroindicadores!G$2) -> 9.715686 | BM6: =IF(ISBLANK(W6),"",AY6/Macroindicadores!H$2) -> 9.715686 | BN6: =IF(ISBLANK(X6),"",AZ6/Macroindicadores!I$2) -> 9.715686 | ... BR6: =IF(ISBLANK(AB6),"",BD6/Macroindicadores!M$2) -> 9.715686 | BS6: =IF(AND(ISBLANK($Q6),ISBLANK($R6),ISBLANK($S6),ISBLANK($T6),ISBLANK($U6),ISBLANK($V6),ISBLANK($W6),ISBLANK($X6),ISBLANK($Y6),ISBLANK($Z6),ISBLANK($AA6),ISBLANK($AB6)),"",SUM(BG6:BR6)) -> 116.58823 | BT6: =IF(ISBLANK($L6),"",_xlfn.XLOOKUP($L6,'CENTRO CUSTO'!$A:$A,'CENTRO CUSTO'!$E:$E,FALSE,0)) -> G&A BU | BV6: =AC6/BS6 -> 5575.1768
A7: =IF(ISBLANK($F7),"","Budget") -> Budget | B7: =IF(ISBLANK($F7),"",$F$1) -> 2026 | C7: =IF(ISBLANK($L7),"",_xlfn.XLOOKUP($L7,'CENTRO CUSTO'!$A:$A,'CENTRO CUSTO'!F:F,FALSE,0)) -> Martini Meat | D7: =IF(ISBLANK($L7),"",_xlfn.XLOOKUP($L7,'CENTRO CUSTO'!$A:$A,'CENTRO CUSTO'!G:G,FALSE,0)) -> BU-MMAZ | E7: =IF(ISBLANK($L7),"",_xlfn.XLOOKUP($L7,'CENTRO CUSTO'!$A:$A,'CENTRO CUSTO'!H:H,FALSE,0)) -> G&A | F7: OT/SCADA SYSTEMS | G7: Applications support and maintenance | H7: Cybersecurity | I7: Novo | J7: Annual | K7: Alta - Para a operação | L7: BU-MMAZ | TI | M7: =IF(ISBLANK($L7),"",_xlfn.XLOOKUP($L7,'CENTRO CUSTO'!$A:$A,'CENTRO CUSTO'!D:D,FALSE,0)) -> Alexandre Ayabe | N7: Outras licenças | P7: USD | Q7: =78368*Rateio!$E$4/12 -> 6530.6667 | R7: =78368*Rateio!$E$4/12 -> 6530.6667 | S7: =78368*Rateio!$E$4/12 -> 6530.6667 | T7: =78368*Rateio!$E$4/12 -> 6530.6667 | U7: =78368*Rateio!$E$4/12 -> 6530.6667 | V7: =78368*Rateio!$E$4/12 -> 6530.6667 | W7: =78368*Rateio!$E$4/12 -> 6530.6667 | X7: =78368*Rateio!$E$4/12 -> 6530.6667 | ... AB7: =78368*Rateio!$E$4/12 -> 6530.6667 | AC7: =IF(AND(ISBLANK($Q7),ISBLANK($R7),ISBLANK($S7),ISBLANK($T7),ISBLANK($U7),ISBLANK($V7),ISBLANK($W7),ISBLANK($X7),ISBLANK($Y7),ISBLANK($Z7),ISBLANK($AA7),ISBLANK($AB7)),"",SUM(Q7:AB7)) -> 78368 | AE7: =IF(ISBLANK(Q7),"",IF($P7="BRL",Q7,Q7*Macroindicadores!B$2)/1000) -> 38.40032 | AF7: =IF(ISBLANK(R7),"",IF($P7="BRL",R7,R7*Macroindicadores!C$2)/1000) -> 38.40032 | AG7: =IF(ISBLANK(S7),"",IF($P7="BRL",S7,S7*Macroindicadores!D$2)/1000) -> 38.40032 | AH7: =IF(ISBLANK(T7),"",IF($P7="BRL",T7,T7*Macroindicadores!E$2)/1000) -> 38.40032 | AI7: =IF(ISBLANK(U7),"",IF($P7="BRL",U7,U7*Macroindicadores!F$2)/1000) -> 38.40032 | AJ7: =IF(ISBLANK(V7),"",IF($P7="BRL",V7,V7*Macroindicadores!G$2)/1000) -> 38.40032 | AK7: =IF(ISBLANK(W7),"",IF($P7="BRL",W7,W7*Macroindicadores!H$2)/1000) -> 38.40032 | AL7: =IF(ISBLANK(X7),"",IF($P7="BRL",X7,X7*Macroindicadores!I$2)/1000) -> 38.40032 | ... AP7: =IF(ISBLANK(AB7),"",IF($P7="BRL",AB7,AB7*Macroindicadores!M$2)/1000) -> 38.40032 | AQ7: =IF(AND(ISBLANK($Q7),ISBLANK($R7),ISBLANK($S7),ISBLANK($T7),ISBLANK($U7),ISBLANK($V7),ISBLANK($W7),ISBLANK($X7),ISBLANK($Y7),ISBLANK($Z7),ISBLANK($AA7),ISBLANK($AB7)),"",SUM(AE7:AP7)) -> 460.80384 | AS7: =IF(ISBLANK(Q7),"",IF(ISBLANK($O7),AE7,IF($J7="ANUAL",AE7*(1+Macroindicadores!B$7),IF(AND($I7="NOVO",MONTH($O7)=MONTH(AS$4)),AE7*(1+Macroindicadores!B$7),IF(AND($J7="PONTUAL",MONTH($O7)=MONTH(AS$4)),AE7*(1+Macroindicadores!B$7),IF(AND($J7="PONTUAL",MONTH($O7)<MONTH(AS$4)),MIN(AR7:$AS7),IF(AND($I7="NOVO",MONTH($O7)>MONTH(AS$4)),AE7,IF(MONTH($O7)>MONTH(AS$4),AE7,IF(MONTH($O7)=MONTH(AS$4),AE7*(1+Macroindicadores!B$7),AR7))))))))) -> 38.40032 | AT7: =IF(ISBLANK(R7),"",IF(ISBLANK($O7),AF7,IF($J7="ANUAL",AF7*(1+Macroindicadores!C$7),IF(AND($I7="NOVO",MONTH($O7)=MONTH(AT$4)),AF7*(1+Macroindicadores!C$7),IF(AND($J7="PONTUAL",MONTH($O7)=MONTH(AT$4)),AF7*(1+Macroindicadores!C$7),IF(AND($J7="PONTUAL",MONTH($O7)<MONTH(AT$4)),MIN($AS7:AS7),IF(AND($I7="NOVO",MONTH($O7)>MONTH(AT$4)),AF7,IF(MONTH($O7)>MONTH(AT$4),AF7,IF(MONTH($O7)=MONTH(AT$4),AF7*(1+Macroindicadores!C$7),AS7))))))))) -> 38.40032 | AU7: =IF(ISBLANK(S7),"",IF(ISBLANK($O7),AG7,IF($J7="ANUAL",AG7*(1+Macroindicadores!D$7),IF(AND($I7="NOVO",MONTH($O7)=MONTH(AU$4)),AG7*(1+Macroindicadores!D$7),IF(AND($J7="PONTUAL",MONTH($O7)=MONTH(AU$4)),AG7*(1+Macroindicadores!D$7),IF(AND($J7="PONTUAL",MONTH($O7)<MONTH(AU$4)),MIN($AS7:AT7),IF(AND($I7="NOVO",MONTH($O7)>MONTH(AU$4)),AG7,IF(MONTH($O7)>MONTH(AU$4),AG7,IF(MONTH($O7)=MONTH(AU$4),AG7*(1+Macroindicadores!D$7),AT7))))))))) -> 38.40032 | AV7: =IF(ISBLANK(T7),"",IF(ISBLANK($O7),AH7,IF($J7="ANUAL",AH7*(1+Macroindicadores!E$7),IF(AND($I7="NOVO",MONTH($O7)=MONTH(AV$4)),AH7*(1+Macroindicadores!E$7),IF(AND($J7="PONTUAL",MONTH($O7)=MONTH(AV$4)),AH7*(1+Macroindicadores!E$7),IF(AND($J7="PONTUAL",MONTH($O7)<MONTH(AV$4)),MIN($AS7:AU7),IF(AND($I7="NOVO",MONTH($O7)>MONTH(AV$4)),AH7,IF(MONTH($O7)>MONTH(AV$4),AH7,IF(MONTH($O7)=MONTH(AV$4),AH7*(1+Macroindicadores!E$7),AU7))))))))) -> 38.40032 | AW7: =IF(ISBLANK(U7),"",IF(ISBLANK($O7),AI7,IF($J7="ANUAL",AI7*(1+Macroindicadores!F$7),IF(AND($I7="NOVO",MONTH($O7)=MONTH(AW$4)),AI7*(1+Macroindicadores!F$7),IF(AND($J7="PONTUAL",MONTH($O7)=MONTH(AW$4)),AI7*(1+Macroindicadores!F$7),IF(AND($J7="PONTUAL",MONTH($O7)<MONTH(AW$4)),MIN($AS7:AV7),IF(AND($I7="NOVO",MONTH($O7)>MONTH(AW$4)),AI7,IF(MONTH($O7)>MONTH(AW$4),AI7,IF(MONTH($O7)=MONTH(AW$4),AI7*(1+Macroindicadores!F$7),AV7))))))))) -> 38.40032 | AX7: =IF(ISBLANK(V7),"",IF(ISBLANK($O7),AJ7,IF($J7="ANUAL",AJ7*(1+Macroindicadores!G$7),IF(AND($I7="NOVO",MONTH($O7)=MONTH(AX$4)),AJ7*(1+Macroindicadores!G$7),IF(AND($J7="PONTUAL",MONTH($O7)=MONTH(AX$4)),AJ7*(1+Macroindicadores!G$7),IF(AND($J7="PONTUAL",MONTH($O7)<MONTH(AX$4)),MIN($AS7:AW7),IF(AND($I7="NOVO",MONTH($O7)>MONTH(AX$4)),AJ7,IF(MONTH($O7)>MONTH(AX$4),AJ7,IF(MONTH($O7)=MONTH(AX$4),AJ7*(1+Macroindicadores!G$7),AW7))))))))) -> 38.40032 | AY7: =IF(ISBLANK(W7),"",IF(ISBLANK($O7),AK7,IF($J7="ANUAL",AK7*(1+Macroindicadores!H$7),IF(AND($I7="NOVO",MONTH($O7)=MONTH(AY$4)),AK7*(1+Macroindicadores!H$7),IF(AND($J7="PONTUAL",MONTH($O7)=MONTH(AY$4)),AK7*(1+Macroindicadores!H$7),IF(AND($J7="PONTUAL",MONTH($O7)<MONTH(AY$4)),MIN($AS7:AX7),IF(AND($I7="NOVO",MONTH($O7)>MONTH(AY$4)),AK7,IF(MONTH($O7)>MONTH(AY$4),AK7,IF(MONTH($O7)=MONTH(AY$4),AK7*(1+Macroindicadores!H$7),AX7))))))))) -> 38.40032 | AZ7: =IF(ISBLANK(X7),"",IF(ISBLANK($O7),AL7,IF($J7="ANUAL",AL7*(1+Macroindicadores!I$7),IF(AND($I7="NOVO",MONTH($O7)=MONTH(AZ$4)),AL7*(1+Macroindicadores!I$7),IF(AND($J7="PONTUAL",MONTH($O7)=MONTH(AZ$4)),AL7*(1+Macroindicadores!I$7),IF(AND($J7="PONTUAL",MONTH($O7)<MONTH(AZ$4)),MIN($AS7:AY7),IF(AND($I7="NOVO",MONTH($O7)>MONTH(AZ$4)),AL7,IF(MONTH($O7)>MONTH(AZ$4),AL7,IF(MONTH($O7)=MONTH(AZ$4),AL7*(1+Macroindicadores!I$7),AY7))))))))) -> 38.40032 | BA7: =IF(ISBLANK(Y7),"",IF(ISBLANK($O7),AM7,IF($J7="ANUAL",AM7*(1+Macroindicadores!J$7),IF(AND($I7="NOVO",MONTH($O7)=MONTH(BA$4)),AM7*(1+Macroindicadores!J$7),IF(AND($J7="PONTUAL",MONTH($O7)=MONTH(BA$4)),AM7*(1+Macroindicadores!J$7),IF(AND($J7="PONTUAL",MONTH($O7)<MONTH(BA$4)),MIN($AS7:AZ7),IF(AND($I7="NOVO",MONTH($O7)>MONTH(BA$4)),AM7,IF(MONTH($O7)>MONTH(BA$4),AM7,IF(MONTH($O7)=MONTH(BA$4),AM7*(1+Macroindicadores!J$7),AZ7))))))))) -> 38.40032 | ... BD7: =IF(ISBLANK(AB7),"",IF(ISBLANK($O7),AP7,IF($J7="ANUAL",AP7*(1+Macroindicadores!M$7),IF(AND($I7="NOVO",MONTH($O7)=MONTH(BD$4)),AP7*(1+Macroindicadores!M$7),IF(AND($J7="PONTUAL",MONTH($O7)=MONTH(BD$4)),AP7*(1+Macroindicadores!M$7),IF(AND($J7="PONTUAL",MONTH($O7)<MONTH(BD$4)),MIN($AS7:BC7),IF(AND($I7="NOVO",MONTH($O7)>MONTH(BD$4)),AP7,IF(MONTH($O7)>MONTH(BD$4),AP7,IF(MONTH($O7)=MONTH(BD$4),AP7*(1+Macroindicadores!M$7),BC7))))))))) -> 38.40032 | BE7: =IF(AND(ISBLANK($Q7),ISBLANK($R7),ISBLANK($S7),ISBLANK($T7),ISBLANK($U7),ISBLANK($V7),ISBLANK($W7),ISBLANK($X7),ISBLANK($Y7),ISBLANK($Z7),ISBLANK($AA7),ISBLANK($AB7)),"",SUM(AS7:BD7)) -> 460.80384 | BG7: =IF(ISBLANK(Q7),"",AS7/Macroindicadores!B$2) -> 6.5306667 | BH7: =IF(ISBLANK(R7),"",AT7/Macroindicadores!C$2) -> 6.5306667 | BI7: =IF(ISBLANK(S7),"",AU7/Macroindicadores!D$2) -> 6.5306667 | BJ7: =IF(ISBLANK(T7),"",AV7/Macroindicadores!E$2) -> 6.5306667 | BK7: =IF(ISBLANK(U7),"",AW7/Macroindicadores!F$2) -> 6.5306667 | BL7: =IF(ISBLANK(V7),"",AX7/Macroindicadores!G$2) -> 6.5306667 | BM7: =IF(ISBLANK(W7),"",AY7/Macroindicadores!H$2) -> 6.5306667 | BN7: =IF(ISBLANK(X7),"",AZ7/Macroindicadores!I$2) -> 6.5306667 | ... BR7: =IF(ISBLANK(AB7),"",BD7/Macroindicadores!M$2) -> 6.5306667 | BS7: =IF(AND(ISBLANK($Q7),ISBLANK($R7),ISBLANK($S7),ISBLANK($T7),ISBLANK($U7),ISBLANK($V7),ISBLANK($W7),ISBLANK($X7),ISBLANK($Y7),ISBLANK($Z7),ISBLANK($AA7),ISBLANK($AB7)),"",SUM(BG7:BR7)) -> 78.368 | BT7: =IF(ISBLANK($L7),"",_xlfn.XLOOKUP($L7,'CENTRO CUSTO'!$A:$A,'CENTRO CUSTO'!$E:$E,FALSE,0)) -> G&A BU
A8: =IF(ISBLANK($F8),"","Budget") -> Budget | B8: =IF(ISBLANK($F8),"",$F$1) -> 2026 | C8: =IF(ISBLANK($L8),"",_xlfn.XLOOKUP($L8,'CENTRO CUSTO'!$A:$A,'CENTRO CUSTO'!F:F,FALSE,0)) -> Transporte | D8: =IF(ISBLANK($L8),"",_xlfn.XLOOKUP($L8,'CENTRO CUSTO'!$A:$A,'CENTRO CUSTO'!G:G,FALSE,0)) -> BU-TR | E8: =IF(ISBLANK($L8),"",_xlfn.XLOOKUP($L8,'CENTRO CUSTO'!$A:$A,'CENTRO CUSTO'!H:H,FALSE,0)) -> G&A | F8: RAVANEDA | G8: Applications support and maintenance | H8: SAP R3 - AMS | I8: Existente | J8: Mensal | K8: Contrato em Curso | L8: BU-MMTR | TI | M8: =IF(ISBLANK($L8),"",_xlfn.XLOOKUP($L8,'CENTRO CUSTO'!$A:$A,'CENTRO CUSTO'!D:D,FALSE,0)) -> Alexandre Ayabe | N8: Manutenção de Informática | P8: BRL | Q8: =35000*Rateio!$E$3 -> 0 | R8: =35000*Rateio!$E$3 -> 0 | S8: =35000*Rateio!$E$3 -> 0 | AC8: =IF(AND(ISBLANK($Q8),ISBLANK($R8),ISBLANK($S8),ISBLANK($T8),ISBLANK($U8),ISBLANK($V8),ISBLANK($W8),ISBLANK($X8),ISBLANK($Y8),ISBLANK($Z8),ISBLANK($AA8),ISBLANK($AB8)),"",SUM(Q8:AB8)) -> 0 | AE8: =IF(ISBLANK(Q8),"",IF($P8="BRL",Q8,Q8*Macroindicadores!B$2)/1000) -> 0 | AF8: =IF(ISBLANK(R8),"",IF($P8="BRL",R8,R8*Macroindicadores!C$2)/1000) -> 0 | AG8: =IF(ISBLANK(S8),"",IF($P8="BRL",S8,S8*Macroindicadores!D$2)/1000) -> 0 | AH8: =IF(ISBLANK(T8),"",IF($P8="BRL",T8,T8*Macroindicadores!E$2)/1000) | AI8: =IF(ISBLANK(U8),"",IF($P8="BRL",U8,U8*Macroindicadores!F$2)/1000) | AJ8: =IF(ISBLANK(V8),"",IF($P8="BRL",V8,V8*Macroindicadores!G$2)/1000) | AK8: =IF(ISBLANK(W8),"",IF($P8="BRL",W8,W8*Macroindicadores!H$2)/1000) | AL8: =IF(ISBLANK(X8),"",IF($P8="BRL",X8,X8*Macroindicadores!I$2)/1000) | ... AP8: =IF(ISBLANK(AB8),"",IF($P8="BRL",AB8,AB8*Macroindicadores!M$2)/1000) | AQ8: =IF(AND(ISBLANK($Q8),ISBLANK($R8),ISBLANK($S8),ISBLANK($T8),ISBLANK($U8),ISBLANK($V8),ISBLANK($W8),ISBLANK($X8),ISBLANK($Y8),ISBLANK($Z8),ISBLANK($AA8),ISBLANK($AB8)),"",SUM(AE8:AP8)) -> 0 | AS8: =IF(ISBLANK(Q8),"",IF(ISBLANK($O8),AE8,IF($J8="ANUAL",AE8*(1+Macroindicadores!B$7),IF(AND($I8="NOVO",MONTH($O8)=MONTH(AS$4)),AE8*(1+Macroindicadores!B$7),IF(AND($J8="PONTUAL",MONTH($O8)=MONTH(AS$4)),AE8*(1+Macroindicadores!B$7),IF(AND($J8="PONTUAL",MONTH($O8)<MONTH(AS$4)),MIN(AR8:$AS8),IF(AND($I8="NOVO",MONTH($O8)>MONTH(AS$4)),AE8,IF(MONTH($O8)>MONTH(AS$4),AE8,IF(MONTH($O8)=MONTH(AS$4),AE8*(1+Macroindicadores!B$7),AR8))))))))) -> 0 | AT8: =IF(ISBLANK(R8),"",IF(ISBLANK($O8),AF8,IF($J8="ANUAL",AF8*(1+Macroindicadores!C$7),IF(AND($I8="NOVO",MONTH($O8)=MONTH(AT$4)),AF8*(1+Macroindicadores!C$7),IF(AND($J8="PONTUAL",MONTH($O8)=MONTH(AT$4)),AF8*(1+Macroindicadores!C$7),IF(AND($J8="PONTUAL",MONTH($O8)<MONTH(AT$4)),MIN($AS8:AS8),IF(AND($I8="NOVO",MONTH($O8)>MONTH(AT$4)),AF8,IF(MONTH($O8)>MONTH(AT$4),AF8,IF(MONTH($O8)=MONTH(AT$4),AF8*(1+Macroindicadores!C$7),AS8))))))))) -> 0 | AU8: =IF(ISBLANK(S8),"",IF(ISBLANK($O8),AG8,IF($J8="ANUAL",AG8*(1+Macroindicadores!D$7),IF(AND($I8="NOVO",MONTH($O8)=MONTH(AU$4)),AG8*(1+Macroindicadores!D$7),IF(AND($J8="PONTUAL",MONTH($O8)=MONTH(AU$4)),AG8*(1+Macroindicadores!D$7),IF(AND($J8="PONTUAL",MONTH($O8)<MONTH(AU$4)),MIN($AS8:AT8),IF(AND($I8="NOVO",MONTH($O8)>MONTH(AU$4)),AG8,IF(MONTH($O8)>MONTH(AU$4),AG8,IF(MONTH($O8)=MONTH(AU$4),AG8*(1+Macroindicadores!D$7),AT8))))))))) -> 0 | AV8: =IF(ISBLANK(T8),"",IF(ISBLANK($O8),AH8,IF($J8="ANUAL",AH8*(1+Macroindicadores!E$7),IF(AND($I8="NOVO",MONTH($O8)=MONTH(AV$4)),AH8*(1+Macroindicadores!E$7),IF(AND($J8="PONTUAL",MONTH($O8)=MONTH(AV$4)),AH8*(1+Macroindicadores!E$7),IF(AND($J8="PONTUAL",MONTH($O8)<MONTH(AV$4)),MIN($AS8:AU8),IF(AND($I8="NOVO",MONTH($O8)>MONTH(AV$4)),AH8,IF(MONTH($O8)>MONTH(AV$4),AH8,IF(MONTH($O8)=MONTH(AV$4),AH8*(1+Macroindicadores!E$7),AU8))))))))) | AW8: =IF(ISBLANK(U8),"",IF(ISBLANK($O8),AI8,IF($J8="ANUAL",AI8*(1+Macroindicadores!F$7),IF(AND($I8="NOVO",MONTH($O8)=MONTH(AW$4)),AI8*(1+Macroindicadores!F$7),IF(AND($J8="PONTUAL",MONTH($O8)=MONTH(AW$4)),AI8*(1+Macroindicadores!F$7),IF(AND($J8="PONTUAL",MONTH($O8)<MONTH(AW$4)),MIN($AS8:AV8),IF(AND($I8="NOVO",MONTH($O8)>MONTH(AW$4)),AI8,IF(MONTH($O8)>MONTH(AW$4),AI8,IF(MONTH($O8)=MONTH(AW$4),AI8*(1+Macroindicadores!F$7),AV8))))))))) | AX8: =IF(ISBLANK(V8),"",IF(ISBLANK($O8),AJ8,IF($J8="ANUAL",AJ8*(1+Macroindicadores!G$7),IF(AND($I8="NOVO",MONTH($O8)=MONTH(AX$4)),AJ8*(1+Macroindicadores!G$7),IF(AND($J8="PONTUAL",MONTH($O8)=MONTH(AX$4)),AJ8*(1+Macroindicadores!G$7),IF(AND($J8="PONTUAL",MONTH($O8)<MONTH(AX$4)),MIN($AS8:AW8),IF(AND($I8="NOVO",MONTH($O8)>MONTH(AX$4)),AJ8,IF(MONTH($O8)>MONTH(AX$4),AJ8,IF(MONTH($O8)=MONTH(AX$4),AJ8*(1+Macroindicadores!G$7),AW8))))))))) | AY8: =IF(ISBLANK(W8),"",IF(ISBLANK($O8),AK8,IF($J8="ANUAL",AK8*(1+Macroindicadores!H$7),IF(AND($I8="NOVO",MONTH($O8)=MONTH(AY$4)),AK8*(1+Macroindicadores!H$7),IF(AND($J8="PONTUAL",MONTH($O8)=MONTH(AY$4)),AK8*(1+Macroindicadores!H$7),IF(AND($J8="PONTUAL",MONTH($O8)<MONTH(AY$4)),MIN($AS8:AX8),IF(AND($I8="NOVO",MONTH($O8)>MONTH(AY$4)),AK8,IF(MONTH($O8)>MONTH(AY$4),AK8,IF(MONTH($O8)=MONTH(AY$4),AK8*(1+Macroindicadores!H$7),AX8))))))))) | AZ8: =IF(ISBLANK(X8),"",IF(ISBLANK($O8),AL8,IF($J8="ANUAL",AL8*(1+Macroindicadores!I$7),IF(AND($I8="NOVO",MONTH($O8)=MONTH(AZ$4)),AL8*(1+Macroindicadores!I$7),IF(AND($J8="PONTUAL",MONTH($O8)=MONTH(AZ$4)),AL8*(1+Macroindicadores!I$7),IF(AND($J8="PONTUAL",MONTH($O8)<MONTH(AZ$4)),MIN($AS8:AY8),IF(AND($I8="NOVO",MONTH($O8)>MONTH(AZ$4)),AL8,IF(MONTH($O8)>MONTH(AZ$4),AL8,IF(MONTH($O8)=MONTH(AZ$4),AL8*(1+Macroindicadores!I$7),AY8))))))))) | BA8: =IF(ISBLANK(Y8),"",IF(ISBLANK($O8),AM8,IF($J8="ANUAL",AM8*(1+Macroindicadores!J$7),IF(AND($I8="NOVO",MONTH($O8)=MONTH(BA$4)),AM8*(1+Macroindicadores!J$7),IF(AND($J8="PONTUAL",MONTH($O8)=MONTH(BA$4)),AM8*(1+Macroindicadores!J$7),IF(AND($J8="PONTUAL",MONTH($O8)<MONTH(BA$4)),MIN($AS8:AZ8),IF(AND($I8="NOVO",MONTH($O8)>MONTH(BA$4)),AM8,IF(MONTH($O8)>MONTH(BA$4),AM8,IF(MONTH($O8)=MONTH(BA$4),AM8*(1+Macroindicadores!J$7),AZ8))))))))) | ... BD8: =IF(ISBLANK(AB8),"",IF(ISBLANK($O8),AP8,IF($J8="ANUAL",AP8*(1+Macroindicadores!M$7),IF(AND($I8="NOVO",MONTH($O8)=MONTH(BD$4)),AP8*(1+Macroindicadores!M$7),IF(AND($J8="PONTUAL",MONTH($O8)=MONTH(BD$4)),AP8*(1+Macroindicadores!M$7),IF(AND($J8="PONTUAL",MONTH($O8)<MONTH(BD$4)),MIN($AS8:BC8),IF(AND($I8="NOVO",MONTH($O8)>MONTH(BD$4)),AP8,IF(MONTH($O8)>MONTH(BD$4),AP8,IF(MONTH($O8)=MONTH(BD$4),AP8*(1+Macroindicadores!M$7),BC8))))))))) | BE8: =IF(AND(ISBLANK($Q8),ISBLANK($R8),ISBLANK($S8),ISBLANK($T8),ISBLANK($U8),ISBLANK($V8),ISBLANK($W8),ISBLANK($X8),ISBLANK($Y8),ISBLANK($Z8),ISBLANK($AA8),ISBLANK($AB8)),"",SUM(AS8:BD8)) -> 0 | BG8: =IF(ISBLANK(Q8),"",AS8/Macroindicadores!B$2) -> 0 | BH8: =IF(ISBLANK(R8),"",AT8/Macroindicadores!C$2) -> 0 | BI8: =IF(ISBLANK(S8),"",AU8/Macroindicadores!D$2) -> 0 | BJ8: =IF(ISBLANK(T8),"",AV8/Macroindicadores!E$2) | BK8: =IF(ISBLANK(U8),"",AW8/Macroindicadores!F$2) | BL8: =IF(ISBLANK(V8),"",AX8/Macroindicadores!G$2) | BM8: =IF(ISBLANK(W8),"",AY8/Macroindicadores!H$2) | BN8: =IF(ISBLANK(X8),"",AZ8/Macroindicadores!I$2) | ... BR8: =IF(ISBLANK(AB8),"",BD8/Macroindicadores!M$2) | BS8: =IF(AND(ISBLANK($Q8),ISBLANK($R8),ISBLANK($S8),ISBLANK($T8),ISBLANK($U8),ISBLANK($V8),ISBLANK($W8),ISBLANK($X8),ISBLANK($Y8),ISBLANK($Z8),ISBLANK($AA8),ISBLANK($AB8)),"",SUM(BG8:BR8)) -> 0 | BT8: =IF(ISBLANK($L8),"",_xlfn.XLOOKUP($L8,'CENTRO CUSTO'!$A:$A,'CENTRO CUSTO'!$E:$E,FALSE,0)) -> G&A BU
A9: =IF(ISBLANK($F9),"","Budget") -> Budget | B9: =IF(ISBLANK($F9),"",$F$1) -> 2026 | C9: =IF(ISBLANK($L9),"",_xlfn.XLOOKUP($L9,'CENTRO CUSTO'!$A:$A,'CENTRO CUSTO'!F:F,FALSE,0)) -> Martini Meat | D9: =IF(ISBLANK($L9),"",_xlfn.XLOOKUP($L9,'CENTRO CUSTO'!$A:$A,'CENTRO CUSTO'!G:G,FALSE,0)) -> BU-MMAZ | E9: =IF(ISBLANK($L9),"",_xlfn.XLOOKUP($L9,'CENTRO CUSTO'!$A:$A,'CENTRO CUSTO'!H:H,FALSE,0)) -> G&A | F9: RAVANEDA | G9: Applications support and maintenance | H9: SAP R3 - AMS | I9: Existente | J9: Mensal | K9: Contrato em Curso | L9: BU-MMAZ | TI | M9: =IF(ISBLANK($L9),"",_xlfn.XLOOKUP($L9,'CENTRO CUSTO'!$A:$A,'CENTRO CUSTO'!D:D,FALSE,0)) -> Alexandre Ayabe | N9: Manutenção de Informática | P9: BRL | Q9: =35000*Rateio!$E$4 -> 35000 | R9: =35000*Rateio!$E$4 -> 35000 | S9: =35000*Rateio!$E$4 -> 35000 | AC9: =IF(AND(ISBLANK($Q9),ISBLANK($R9),ISBLANK($S9),ISBLANK($T9),ISBLANK($U9),ISBLANK($V9),ISBLANK($W9),ISBLANK($X9),ISBLANK($Y9),ISBLANK($Z9),ISBLANK($AA9),ISBLANK($AB9)),"",SUM(Q9:AB9)) -> 105000 | AE9: =IF(ISBLANK(Q9),"",IF($P9="BRL",Q9,Q9*Macroindicadores!B$2)/1000) -> 35 | AF9: =IF(ISBLANK(R9),"",IF($P9="BRL",R9,R9*Macroindicadores!C$2)/1000) -> 35 | AG9: =IF(ISBLANK(S9),"",IF($P9="BRL",S9,S9*Macroindicadores!D$2)/1000) -> 35 | AH9: =IF(ISBLANK(T9),"",IF($P9="BRL",T9,T9*Macroindicadores!E$2)/1000) | AI9: =IF(ISBLANK(U9),"",IF($P9="BRL",U9,U9*Macroindicadores!F$2)/1000) | AJ9: =IF(ISBLANK(V9),"",IF($P9="BRL",V9,V9*Macroindicadores!G$2)/1000) | AK9: =IF(ISBLANK(W9),"",IF($P9="BRL",W9,W9*Macroindicadores!H$2)/1000) | AL9: =IF(ISBLANK(X9),"",IF($P9="BRL",X9,X9*Macroindicadores!I$2)/1000) | ... AP9: =IF(ISBLANK(AB9),"",IF($P9="BRL",AB9,AB9*Macroindicadores!M$2)/1000) | AQ9: =IF(AND(ISBLANK($Q9),ISBLANK($R9),ISBLANK($S9),ISBLANK($T9),ISBLANK($U9),ISBLANK($V9),ISBLANK($W9),ISBLANK($X9),ISBLANK($Y9),ISBLANK($Z9),ISBLANK($AA9),ISBLANK($AB9)),"",SUM(AE9:AP9)) -> 105 | AS9: =IF(ISBLANK(Q9),"",IF(ISBLANK($O9),AE9,IF($J9="ANUAL",AE9*(1+Macroindicadores!B$7),IF(AND($I9="NOVO",MONTH($O9)=MONTH(AS$4)),AE9*(1+Macroindicadores!B$7),IF(AND($J9="PONTUAL",MONTH($O9)=MONTH(AS$4)),AE9*(1+Macroindicadores!B$7),IF(AND($J9="PONTUAL",MONTH($O9)<MONTH(AS$4)),MIN(AR9:$AS9),IF(AND($I9="NOVO",MONTH($O9)>MONTH(AS$4)),AE9,IF(MONTH($O9)>MONTH(AS$4),AE9,IF(MONTH($O9)=MONTH(AS$4),AE9*(1+Macroindicadores!B$7),AR9))))))))) -> 35 | AT9: =IF(ISBLANK(R9),"",IF(ISBLANK($O9),AF9,IF($J9="ANUAL",AF9*(1+Macroindicadores!C$7),IF(AND($I9="NOVO",MONTH($O9)=MONTH(AT$4)),AF9*(1+Macroindicadores!C$7),IF(AND($J9="PONTUAL",MONTH($O9)=MONTH(AT$4)),AF9*(1+Macroindicadores!C$7),IF(AND($J9="PONTUAL",MONTH($O9)<MONTH(AT$4)),MIN($AS9:AS9),IF(AND($I9="NOVO",MONTH($O9)>MONTH(AT$4)),AF9,IF(MONTH($O9)>MONTH(AT$4),AF9,IF(MONTH($O9)=MONTH(AT$4),AF9*(1+Macroindicadores!C$7),AS9))))))))) -> 35 | AU9: =IF(ISBLANK(S9),"",IF(ISBLANK($O9),AG9,IF($J9="ANUAL",AG9*(1+Macroindicadores!D$7),IF(AND($I9="NOVO",MONTH($O9)=MONTH(AU$4)),AG9*(1+Macroindicadores!D$7),IF(AND($J9="PONTUAL",MONTH($O9)=MONTH(AU$4)),AG9*(1+Macroindicadores!D$7),IF(AND($J9="PONTUAL",MONTH($O9)<MONTH(AU$4)),MIN($AS9:AT9),IF(AND($I9="NOVO",MONTH($O9)>MONTH(AU$4)),AG9,IF(MONTH($O9)>MONTH(AU$4),AG9,IF(MONTH($O9)=MONTH(AU$4),AG9*(1+Macroindicadores!D$7),AT9))))))))) -> 35 | AV9: =IF(ISBLANK(T9),"",IF(ISBLANK($O9),AH9,IF($J9="ANUAL",AH9*(1+Macroindicadores!E$7),IF(AND($I9="NOVO",MONTH($O9)=MONTH(AV$4)),AH9*(1+Macroindicadores!E$7),IF(AND($J9="PONTUAL",MONTH($O9)=MONTH(AV$4)),AH9*(1+Macroindicadores!E$7),IF(AND($J9="PONTUAL",MONTH($O9)<MONTH(AV$4)),MIN($AS9:AU9),IF(AND($I9="NOVO",MONTH($O9)>MONTH(AV$4)),AH9,IF(MONTH($O9)>MONTH(AV$4),AH9,IF(MONTH($O9)=MONTH(AV$4),AH9*(1+Macroindicadores!E$7),AU9))))))))) | AW9: =IF(ISBLANK(U9),"",IF(ISBLANK($O9),AI9,IF($J9="ANUAL",AI9*(1+Macroindicadores!F$7),IF(AND($I9="NOVO",MONTH($O9)=MONTH(AW$4)),AI9*(1+Macroindicadores!F$7),IF(AND($J9="PONTUAL",MONTH($O9)=MONTH(AW$4)),AI9*(1+Macroindicadores!F$7),IF(AND($J9="PONTUAL",MONTH($O9)<MONTH(AW$4)),MIN($AS9:AV9),IF(AND($I9="NOVO",MONTH($O9)>MONTH(AW$4)),AI9,IF(MONTH($O9)>MONTH(AW$4),AI9,IF(MONTH($O9)=MONTH(AW$4),AI9*(1+Macroindicadores!F$7),AV9))))))))) | AX9: =IF(ISBLANK(V9),"",IF(ISBLANK($O9),AJ9,IF($J9="ANUAL",AJ9*(1+Macroindicadores!G$7),IF(AND($I9="NOVO",MONTH($O9)=MONTH(AX$4)),AJ9*(1+Macroindicadores!G$7),IF(AND($J9="PONTUAL",MONTH($O9)=MONTH(AX$4)),AJ9*(1+Macroindicadores!G$7),IF(AND($J9="PONTUAL",MONTH($O9)<MONTH(AX$4)),MIN($AS9:AW9),IF(AND($I9="NOVO",MONTH($O9)>MONTH(AX$4)),AJ9,IF(MONTH($O9)>MONTH(AX$4),AJ9,IF(MONTH($O9)=MONTH(AX$4),AJ9*(1+Macroindicadores!G$7),AW9))))))))) | AY9: =IF(ISBLANK(W9),"",IF(ISBLANK($O9),AK9,IF($J9="ANUAL",AK9*(1+Macroindicadores!H$7),IF(AND($I9="NOVO",MONTH($O9)=MONTH(AY$4)),AK9*(1+Macroindicadores!H$7),IF(AND($J9="PONTUAL",MONTH($O9)=MONTH(AY$4)),AK9*(1+Macroindicadores!H$7),IF(AND($J9="PONTUAL",MONTH($O9)<MONTH(AY$4)),MIN($AS9:AX9),IF(AND($I9="NOVO",MONTH($O9)>MONTH(AY$4)),AK9,IF(MONTH($O9)>MONTH(AY$4),AK9,IF(MONTH($O9)=MONTH(AY$4),AK9*(1+Macroindicadores!H$7),AX9))))))))) | AZ9: =IF(ISBLANK(X9),"",IF(ISBLANK($O9),AL9,IF($J9="ANUAL",AL9*(1+Macroindicadores!I$7),IF(AND($I9="NOVO",MONTH($O9)=MONTH(AZ$4)),AL9*(1+Macroindicadores!I$7),IF(AND($J9="PONTUAL",MONTH($O9)=MONTH(AZ$4)),AL9*(1+Macroindicadores!I$7),IF(AND($J9="PONTUAL",MONTH($O9)<MONTH(AZ$4)),MIN($AS9:AY9),IF(AND($I9="NOVO",MONTH($O9)>MONTH(AZ$4)),AL9,IF(MONTH($O9)>MONTH(AZ$4),AL9,IF(MONTH($O9)=MONTH(AZ$4),AL9*(1+Macroindicadores!I$7),AY9))))))))) | BA9: =IF(ISBLANK(Y9),"",IF(ISBLANK($O9),AM9,IF($J9="ANUAL",AM9*(1+Macroindicadores!J$7),IF(AND($I9="NOVO",MONTH($O9)=MONTH(BA$4)),AM9*(1+Macroindicadores!J$7),IF(AND($J9="PONTUAL",MONTH($O9)=MONTH(BA$4)),AM9*(1+Macroindicadores!J$7),IF(AND($J9="PONTUAL",MONTH($O9)<MONTH(BA$4)),MIN($AS9:AZ9),IF(AND($I9="NOVO",MONTH($O9)>MONTH(BA$4)),AM9,IF(MONTH($O9)>MONTH(BA$4),AM9,IF(MONTH($O9)=MONTH(BA$4),AM9*(1+Macroindicadores!J$7),AZ9))))))))) | ... BD9: =IF(ISBLANK(AB9),"",IF(ISBLANK($O9),AP9,IF($J9="ANUAL",AP9*(1+Macroindicadores!M$7),IF(AND($I9="NOVO",MONTH($O9)=MONTH(BD$4)),AP9*(1+Macroindicadores!M$7),IF(AND($J9="PONTUAL",MONTH($O9)=MONTH(BD$4)),AP9*(1+Macroindicadores!M$7),IF(AND($J9="PONTUAL",MONTH($O9)<MONTH(BD$4)),MIN($AS9:BC9),IF(AND($I9="NOVO",MONTH($O9)>MONTH(BD$4)),AP9,IF(MONTH($O9)>MONTH(BD$4),AP9,IF(MONTH($O9)=MONTH(BD$4),AP9*(1+Macroindicadores!M$7),BC9))))))))) | BE9: =IF(AND(ISBLANK($Q9),ISBLANK($R9),ISBLANK($S9),ISBLANK($T9),ISBLANK($U9),ISBLANK($V9),ISBLANK($W9),ISBLANK($X9),ISBLANK($Y9),ISBLANK($Z9),ISBLANK($AA9),ISBLANK($AB9)),"",SUM(AS9:BD9)) -> 105 | BG9: =IF(ISBLANK(Q9),"",AS9/Macroindicadores!B$2) -> 5.952381 | BH9: =IF(ISBLANK(R9),"",AT9/Macroindicadores!C$2) -> 5.952381 | BI9: =IF(ISBLANK(S9),"",AU9/Macroindicadores!D$2) -> 5.952381 | BJ9: =IF(ISBLANK(T9),"",AV9/Macroindicadores!E$2) | BK9: =IF(ISBLANK(U9),"",AW9/Macroindicadores!F$2) | BL9: =IF(ISBLANK(V9),"",AX9/Macroindicadores!G$2) | BM9: =IF(ISBLANK(W9),"",AY9/Macroindicadores!H$2) | BN9: =IF(ISBLANK(X9),"",AZ9/Macroindicadores!I$2) | ... BR9: =IF(ISBLANK(AB9),"",BD9/Macroindicadores!M$2) | BS9: =IF(AND(ISBLANK($Q9),ISBLANK($R9),ISBLANK($S9),ISBLANK($T9),ISBLANK($U9),ISBLANK($V9),ISBLANK($W9),ISBLANK($X9),ISBLANK($Y9),ISBLANK($Z9),ISBLANK($AA9),ISBLANK($AB9)),"",SUM(BG9:BR9)) -> 17.857143 | BT9: =IF(ISBLANK($L9),"",_xlfn.XLOOKUP($L9,'CENTRO CUSTO'!$A:$A,'CENTRO CUSTO'!$E:$E,FALSE,0)) -> G&A BU
A10: =IF(ISBLANK($F10),"","Budget") -> Budget | B10: =IF(ISBLANK($F10),"",$F$1) -> 2026 | C10: =IF(ISBLANK($L10),"",_xlfn.XLOOKUP($L10,'CENTRO CUSTO'!$A:$A,'CENTRO CUSTO'!F:F,FALSE,0)) -> Transporte | D10: =IF(ISBLANK($L10),"",_xlfn.XLOOKUP($L10,'CENTRO CUSTO'!$A:$A,'CENTRO CUSTO'!G:G,FALSE,0)) -> BU-TR | E10: =IF(ISBLANK($L10),"",_xlfn.XLOOKUP($L10,'CENTRO CUSTO'!$A:$A,'CENTRO CUSTO'!H:H,FALSE,0)) -> G&A | F10: SEIDOR | G10: Applications support and maintenance | H10: SAP S4 - Licença | I10: Novo | J10: Mensal | K10: Baixa - Eficiência | L10: BU-MMTR | TI | M10: =IF(ISBLANK($L10),"",_xlfn.XLOOKUP($L10,'CENTRO CUSTO'!$A:$A,'CENTRO CUSTO'!D:D,FALSE,0)) -> Alexandre Ayabe | N10: Licença SAP | P10: USD | Q10: =140276*Rateio!$E$33/12 -> 2104.14 | R10: =140276*Rateio!$E$33/12 -> 2104.14 | S10: =140276*Rateio!$E$33/12 -> 2104.14 | T10: =140276*Rateio!$E$33/12 -> 2104.14 | U10: =140276*Rateio!$E$33/12 -> 2104.14 | V10: =140276*Rateio!$E$33/12 -> 2104.14 | W10: =140276*Rateio!$E$33/12 -> 2104.14 | X10: =140276*Rateio!$E$33/12 -> 2104.14 | ... AB10: =140276*Rateio!$E$33/12 -> 2104.14 | AC10: =IF(AND(ISBLANK($Q10),ISBLANK($R10),ISBLANK($S10),ISBLANK($T10),ISBLANK($U10),ISBLANK($V10),ISBLANK($W10),ISBLANK($X10),ISBLANK($Y10),ISBLANK($Z10),ISBLANK($AA10),ISBLANK($AB10)),"",SUM(Q10:AB10)) -> 25249.68 | AE10: =IF(ISBLANK(Q10),"",IF($P10="BRL",Q10,Q10*Macroindicadores!B$2)/1000) -> 12.372343 | AF10: =IF(ISBLANK(R10),"",IF($P10="BRL",R10,R10*Macroindicadores!C$2)/1000) -> 12.372343 | AG10: =IF(ISBLANK(S10),"",IF($P10="BRL",S10,S10*Macroindicadores!D$2)/1000) -> 12.372343 | AH10: =IF(ISBLANK(T10),"",IF($P10="BRL",T10,T10*Macroindicadores!E$2)/1000) -> 12.372343 | AI10: =IF(ISBLANK(U10),"",IF($P10="BRL",U10,U10*Macroindicadores!F$2)/1000) -> 12.372343 | AJ10: =IF(ISBLANK(V10),"",IF($P10="BRL",V10,V10*Macroindicadores!G$2)/1000) -> 12.372343 | AK10: =IF(ISBLANK(W10),"",IF($P10="BRL",W10,W10*Macroindicadores!H$2)/1000) -> 12.372343 | AL10: =IF(ISBLANK(X10),"",IF($P10="BRL",X10,X10*Macroindicadores!I$2)/1000) -> 12.372343 | ... AP10: =IF(ISBLANK(AB10),"",IF($P10="BRL",AB10,AB10*Macroindicadores!M$2)/1000) -> 12.372343 | AQ10: =IF(AND(ISBLANK($Q10),ISBLANK($R10),ISBLANK($S10),ISBLANK($T10),ISBLANK($U10),ISBLANK($V10),ISBLANK($W10),ISBLANK($X10),ISBLANK($Y10),ISBLANK($Z10),ISBLANK($AA10),ISBLANK($AB10)),"",SUM(AE10:AP10)) -> 148.46812 | AS10: =IF(ISBLANK(Q10),"",IF(ISBLANK($O10),AE10,IF($J10="ANUAL",AE10*(1+Macroindicadores!B$7),IF(AND($I10="NOVO",MONTH($O10)=MONTH(AS$4)),AE10*(1+Macroindicadores!B$7),IF(AND($J10="PONTUAL",MONTH($O10)=MONTH(AS$4)),AE10*(1+Macroindicadores!B$7),IF(AND($J10="PONTUAL",MONTH($O10)<MONTH(AS$4)),MIN(AR10:$AS10),IF(AND($I10="NOVO",MONTH($O10)>MONTH(AS$4)),AE10,IF(MONTH($O10)>MONTH(AS$4),AE10,IF(MONTH($O10)=MONTH(AS$4),AE10*(1+Macroindicadores!B$7),AR10))))))))) -> 12.372343 | AT10: =IF(ISBLANK(R10),"",IF(ISBLANK($O10),AF10,IF($J10="ANUAL",AF10*(1+Macroindicadores!C$7),IF(AND($I10="NOVO",MONTH($O10)=MONTH(AT$4)),AF10*(1+Macroindicadores!C$7),IF(AND($J10="PONTUAL",MONTH($O10)=MONTH(AT$4)),AF10*(1+Macroindicadores!C$7),IF(AND($J10="PONTUAL",MONTH($O10)<MONTH(AT$4)),MIN($AS10:AS10),IF(AND($I10="NOVO",MONTH($O10)>MONTH(AT$4)),AF10,IF(MONTH($O10)>MONTH(AT$4),AF10,IF(MONTH($O10)=MONTH(AT$4),AF10*(1+Macroindicadores!C$7),AS10))))))))) -> 12.372343 | AU10: =IF(ISBLANK(S10),"",IF(ISBLANK($O10),AG10,IF($J10="ANUAL",AG10*(1+Macroindicadores!D$7),IF(AND($I10="NOVO",MONTH($O10)=MONTH(AU$4)),AG10*(1+Macroindicadores!D$7),IF(AND($J10="PONTUAL",MONTH($O10)=MONTH(AU$4)),AG10*(1+Macroindicadores!D$7),IF(AND($J10="PONTUAL",MONTH($O10)<MONTH(AU$4)),MIN($AS10:AT10),IF(AND($I10="NOVO",MONTH($O10)>MONTH(AU$4)),AG10,IF(MONTH($O10)>MONTH(AU$4),AG10,IF(MONTH($O10)=MONTH(AU$4),AG10*(1+Macroindicadores!D$7),AT10))))))))) -> 12.372343 | AV10: =IF(ISBLANK(T10),"",IF(ISBLANK($O10),AH10,IF($J10="ANUAL",AH10*(1+Macroindicadores!E$7),IF(AND($I10="NOVO",MONTH($O10)=MONTH(AV$4)),AH10*(1+Macroindicadores!E$7),IF(AND($J10="PONTUAL",MONTH($O10)=MONTH(AV$4)),AH10*(1+Macroindicadores!E$7),IF(AND($J10="PONTUAL",MONTH($O10)<MONTH(AV$4)),MIN($AS10:AU10),IF(AND($I10="NOVO",MONTH($O10)>MONTH(AV$4)),AH10,IF(MONTH($O10)>MONTH(AV$4),AH10,IF(MONTH($O10)=MONTH(AV$4),AH10*(1+Macroindicadores!E$7),AU10))))))))) -> 12.372343 | AW10: =IF(ISBLANK(U10),"",IF(ISBLANK($O10),AI10,IF($J10="ANUAL",AI10*(1+Macroindicadores!F$7),IF(AND($I10="NOVO",MONTH($O10)=MONTH(AW$4)),AI10*(1+Macroindicadores!F$7),IF(AND($J10="PONTUAL",MONTH($O10)=MONTH(AW$4)),AI10*(1+Macroindicadores!F$7),IF(AND($J10="PONTUAL",MONTH($O10)<MONTH(AW$4)),MIN($AS10:AV10),IF(AND($I10="NOVO",MONTH($O10)>MONTH(AW$4)),AI10,IF(MONTH($O10)>MONTH(AW$4),AI10,IF(MONTH($O10)=MONTH(AW$4),AI10*(1+Macroindicadores!F$7),AV10))))))))) -> 12.372343 | AX10: =IF(ISBLANK(V10),"",IF(ISBLANK($O10),AJ10,IF($J10="ANUAL",AJ10*(1+Macroindicadores!G$7),IF(AND($I10="NOVO",MONTH($O10)=MONTH(AX$4)),AJ10*(1+Macroindicadores!G$7),IF(AND($J10="PONTUAL",MONTH($O10)=MONTH(AX$4)),AJ10*(1+Macroindicadores!G$7),IF(AND($J10="PONTUAL",MONTH($O10)<MONTH(AX$4)),MIN($AS10:AW10),IF(AND($I10="NOVO",MONTH($O10)>MONTH(AX$4)),AJ10,IF(MONTH($O10)>MONTH(AX$4),AJ10,IF(MONTH($O10)=MONTH(AX$4),AJ10*(1+Macroindicadores!G$7),AW10))))))))) -> 12.372343 | AY10: =IF(ISBLANK(W10),"",IF(ISBLANK($O10),AK10,IF($J10="ANUAL",AK10*(1+Macroindicadores!H$7),IF(AND($I10="NOVO",MONTH($O10)=MONTH(AY$4)),AK10*(1+Macroindicadores!H$7),IF(AND($J10="PONTUAL",MONTH($O10)=MONTH(AY$4)),AK10*(1+Macroindicadores!H$7),IF(AND($J10="PONTUAL",MONTH($O10)<MONTH(AY$4)),MIN($AS10:AX10),IF(AND($I10="NOVO",MONTH($O10)>MONTH(AY$4)),AK10,IF(MONTH($O10)>MONTH(AY$4),AK10,IF(MONTH($O10)=MONTH(AY$4),AK10*(1+Macroindicadores!H$7),AX10))))))))) -> 12.372343 | AZ10: =IF(ISBLANK(X10),"",IF(ISBLANK($O10),AL10,IF($J10="ANUAL",AL10*(1+Macroindicadores!I$7),IF(AND($I10="NOVO",MONTH($O10)=MONTH(AZ$4)),AL10*(1+Macroindicadores!I$7),IF(AND($J10="PONTUAL",MONTH($O10)=MONTH(AZ$4)),AL10*(1+Macroindicadores!I$7),IF(AND($J10="PONTUAL",MONTH($O10)<MONTH(AZ$4)),MIN($AS10:AY10),IF(AND($I10="NOVO",MONTH($O10)>MONTH(AZ$4)),AL10,IF(MONTH($O10)>MONTH(AZ$4),AL10,IF(MONTH($O10)=MONTH(AZ$4),AL10*(1+Macroindicadores!I$7),AY10))))))))) -> 12.372343 | BA10: =IF(ISBLANK(Y10),"",IF(ISBLANK($O10),AM10,IF($J10="ANUAL",AM10*(1+Macroindicadores!J$7),IF(AND($I10="NOVO",MONTH($O10)=MONTH(BA$4)),AM10*(1+Macroindicadores!J$7),IF(AND($J10="PONTUAL",MONTH($O10)=MONTH(BA$4)),AM10*(1+Macroindicadores!J$7),IF(AND($J10="PONTUAL",MONTH($O10)<MONTH(BA$4)),MIN($AS10:AZ10),IF(AND($I10="NOVO",MONTH($O10)>MONTH(BA$4)),AM10,IF(MONTH($O10)>MONTH(BA$4),AM10,IF(MONTH($O10)=MONTH(BA$4),AM10*(1+Macroindicadores!J$7),AZ10))))))))) -> 12.372343 | ... BD10: =IF(ISBLANK(AB10),"",IF(ISBLANK($O10),AP10,IF($J10="ANUAL",AP10*(1+Macroindicadores!M$7),IF(AND($I10="NOVO",MONTH($O10)=MONTH(BD$4)),AP10*(1+Macroindicadores!M$7),IF(AND($J10="PONTUAL",MONTH($O10)=MONTH(BD$4)),AP10*(1+Macroindicadores!M$7),IF(AND($J10="PONTUAL",MONTH($O10)<MONTH(BD$4)),MIN($AS10:BC10),IF(AND($I10="NOVO",MONTH($O10)>MONTH(BD$4)),AP10,IF(MONTH($O10)>MONTH(BD$4),AP10,IF(MONTH($O10)=MONTH(BD$4),AP10*(1+Macroindicadores!M$7),BC10))))))))) -> 12.372343 | BE10: =IF(AND(ISBLANK($Q10),ISBLANK($R10),ISBLANK($S10),ISBLANK($T10),ISBLANK($U10),ISBLANK($V10),ISBLANK($W10),ISBLANK($X10),ISBLANK($Y10),ISBLANK($Z10),ISBLANK($AA10),ISBLANK($AB10)),"",SUM(AS10:BD10)) -> 148.46812 | BG10: =IF(ISBLANK(Q10),"",AS10/Macroindicadores!B$2) -> 2.10414 | BH10: =IF(ISBLANK(R10),"",AT10/Macroindicadores!C$2) -> 2.10414 | BI10: =IF(ISBLANK(S10),"",AU10/Macroindicadores!D$2) -> 2.10414 | BJ10: =IF(ISBLANK(T10),"",AV10/Macroindicadores!E$2) -> 2.10414 | BK10: =IF(ISBLANK(U10),"",AW10/Macroindicadores!F$2) -> 2.10414 | BL10: =IF(ISBLANK(V10),"",AX10/Macroindicadores!G$2) -> 2.10414 | BM10: =IF(ISBLANK(W10),"",AY10/Macroindicadores!H$2) -> 2.10414 | BN10: =IF(ISBLANK(X10),"",AZ10/Macroindicadores!I$2) -> 2.10414 | ... BR10: =IF(ISBLANK(AB10),"",BD10/Macroindicadores!M$2) -> 2.10414 | BS10: =IF(AND(ISBLANK($Q10),ISBLANK($R10),ISBLANK($S10),ISBLANK($T10),ISBLANK($U10),ISBLANK($V10),ISBLANK($W10),ISBLANK($X10),ISBLANK($Y10),ISBLANK($Z10),ISBLANK($AA10),ISBLANK($AB10)),"",SUM(BG10:BR10)) -> 25.24968 | BT10: =IF(ISBLANK($L10),"",_xlfn.XLOOKUP($L10,'CENTRO CUSTO'!$A:$A,'CENTRO CUSTO'!$E:$E,FALSE,0)) -> G&A BU
A11: =IF(ISBLANK($F11),"","Budget") -> Budget | B11: =IF(ISBLANK($F11),"",$F$1) -> 2026 | C11: =IF(ISBLANK($L11),"",_xlfn.XLOOKUP($L11,'CENTRO CUSTO'!$A:$A,'CENTRO CUSTO'!F:F,FALSE,0)) -> Martini Meat | D11: =IF(ISBLANK($L11),"",_xlfn.XLOOKUP($L11,'CENTRO CUSTO'!$A:$A,'CENTRO CUSTO'!G:G,FALSE,0)) -> BU-MMAZ | E11: =IF(ISBLANK($L11),"",_xlfn.XLOOKUP($L11,'CENTRO CUSTO'!$A:$A,'CENTRO CUSTO'!H:H,FALSE,0)) -> G&A | F11: SEIDOR | G11: Applications support and maintenance | H11: SAP S4 - Licença | I11: Novo | J11: Mensal | K11: Contrato em Curso | L11: BU-MMAZ | TI | M11: =IF(ISBLANK($L11),"",_xlfn.XLOOKUP($L11,'CENTRO CUSTO'!$A:$A,'CENTRO CUSTO'!D:D,FALSE,0)) -> Alexandre Ayabe | N11: Licença SAP | P11: USD | Q11: =140276*Rateio!$E$34/12 -> 5611.04 | R11: =140276*Rateio!$E$34/12 -> 5611.04 | S11: =140276*Rateio!$E$34/12 -> 5611.04 | T11: =140276*Rateio!$E$34/12 -> 5611.04 | U11: =140276*Rateio!$E$34/12 -> 5611.04 | V11: =140276*Rateio!$E$34/12 -> 5611.04 | W11: =140276*Rateio!$E$34/12 -> 5611.04 | X11: =140276*Rateio!$E$34/12 -> 5611.04 | ... AB11: =140276*Rateio!$E$34/12 -> 5611.04 | AC11: =IF(AND(ISBLANK($Q11),ISBLANK($R11),ISBLANK($S11),ISBLANK($T11),ISBLANK($U11),ISBLANK($V11),ISBLANK($W11),ISBLANK($X11),ISBLANK($Y11),ISBLANK($Z11),ISBLANK($AA11),ISBLANK($AB11)),"",SUM(Q11:AB11)) -> 67332.48 | AE11: =IF(ISBLANK(Q11),"",IF($P11="BRL",Q11,Q11*Macroindicadores!B$2)/1000) -> 32.992915 | AF11: =IF(ISBLANK(R11),"",IF($P11="BRL",R11,R11*Macroindicadores!C$2)/1000) -> 32.992915 | AG11: =IF(ISBLANK(S11),"",IF($P11="BRL",S11,S11*Macroindicadores!D$2)/1000) -> 32.992915 | AH11: =IF(ISBLANK(T11),"",IF($P11="BRL",T11,T11*Macroindicadores!E$2)/1000) -> 32.992915 | AI11: =IF(ISBLANK(U11),"",IF($P11="BRL",U11,U11*Macroindicadores!F$2)/1000) -> 32.992915 | AJ11: =IF(ISBLANK(V11),"",IF($P11="BRL",V11,V11*Macroindicadores!G$2)/1000) -> 32.992915 | AK11: =IF(ISBLANK(W11),"",IF($P11="BRL",W11,W11*Macroindicadores!H$2)/1000) -> 32.992915 | AL11: =IF(ISBLANK(X11),"",IF($P11="BRL",X11,X11*Macroindicadores!I$2)/1000) -> 32.992915 | ... AP11: =IF(ISBLANK(AB11),"",IF($P11="BRL",AB11,AB11*Macroindicadores!M$2)/1000) -> 32.992915 | AQ11: =IF(AND(ISBLANK($Q11),ISBLANK($R11),ISBLANK($S11),ISBLANK($T11),ISBLANK($U11),ISBLANK($V11),ISBLANK($W11),ISBLANK($X11),ISBLANK($Y11),ISBLANK($Z11),ISBLANK($AA11),ISBLANK($AB11)),"",SUM(AE11:AP11)) -> 395.91498 | AS11: =IF(ISBLANK(Q11),"",IF(ISBLANK($O11),AE11,IF($J11="ANUAL",AE11*(1+Macroindicadores!B$7),IF(AND($I11="NOVO",MONTH($O11)=MONTH(AS$4)),AE11*(1+Macroindicadores!B$7),IF(AND($J11="PONTUAL",MONTH($O11)=MONTH(AS$4)),AE11*(1+Macroindicadores!B$7),IF(AND($J11="PONTUAL",MONTH($O11)<MONTH(AS$4)),MIN(AR11:$AS11),IF(AND($I11="NOVO",MONTH($O11)>MONTH(AS$4)),AE11,IF(MONTH($O11)>MONTH(AS$4),AE11,IF(MONTH($O11)=MONTH(AS$4),AE11*(1+Macroindicadores!B$7),AR11))))))))) -> 32.992915 | AT11: =IF(ISBLANK(R11),"",IF(ISBLANK($O11),AF11,IF($J11="ANUAL",AF11*(1+Macroindicadores!C$7),IF(AND($I11="NOVO",MONTH($O11)=MONTH(AT$4)),AF11*(1+Macroindicadores!C$7),IF(AND($J11="PONTUAL",MONTH($O11)=MONTH(AT$4)),AF11*(1+Macroindicadores!C$7),IF(AND($J11="PONTUAL",MONTH($O11)<MONTH(AT$4)),MIN($AS11:AS11),IF(AND($I11="NOVO",MONTH($O11)>MONTH(AT$4)),AF11,IF(MONTH($O11)>MONTH(AT$4),AF11,IF(MONTH($O11)=MONTH(AT$4),AF11*(1+Macroindicadores!C$7),AS11))))))))) -> 32.992915 | AU11: =IF(ISBLANK(S11),"",IF(ISBLANK($O11),AG11,IF($J11="ANUAL",AG11*(1+Macroindicadores!D$7),IF(AND($I11="NOVO",MONTH($O11)=MONTH(AU$4)),AG11*(1+Macroindicadores!D$7),IF(AND($J11="PONTUAL",MONTH($O11)=MONTH(AU$4)),AG11*(1+Macroindicadores!D$7),IF(AND($J11="PONTUAL",MONTH($O11)<MONTH(AU$4)),MIN($AS11:AT11),IF(AND($I11="NOVO",MONTH($O11)>MONTH(AU$4)),AG11,IF(MONTH($O11)>MONTH(AU$4),AG11,IF(MONTH($O11)=MONTH(AU$4),AG11*(1+Macroindicadores!D$7),AT11))))))))) -> 32.992915 | AV11: =IF(ISBLANK(T11),"",IF(ISBLANK($O11),AH11,IF($J11="ANUAL",AH11*(1+Macroindicadores!E$7),IF(AND($I11="NOVO",MONTH($O11)=MONTH(AV$4)),AH11*(1+Macroindicadores!E$7),IF(AND($J11="PONTUAL",MONTH($O11)=MONTH(AV$4)),AH11*(1+Macroindicadores!E$7),IF(AND($J11="PONTUAL",MONTH($O11)<MONTH(AV$4)),MIN($AS11:AU11),IF(AND($I11="NOVO",MONTH($O11)>MONTH(AV$4)),AH11,IF(MONTH($O11)>MONTH(AV$4),AH11,IF(MONTH($O11)=MONTH(AV$4),AH11*(1+Macroindicadores!E$7),AU11))))))))) -> 32.992915 | AW11: =IF(ISBLANK(U11),"",IF(ISBLANK($O11),AI11,IF($J11="ANUAL",AI11*(1+Macroindicadores!F$7),IF(AND($I11="NOVO",MONTH($O11)=MONTH(AW$4)),AI11*(1+Macroindicadores!F$7),IF(AND($J11="PONTUAL",MONTH($O11)=MONTH(AW$4)),AI11*(1+Macroindicadores!F$7),IF(AND($J11="PONTUAL",MONTH($O11)<MONTH(AW$4)),MIN($AS11:AV11),IF(AND($I11="NOVO",MONTH($O11)>MONTH(AW$4)),AI11,IF(MONTH($O11)>MONTH(AW$4),AI11,IF(MONTH($O11)=MONTH(AW$4),AI11*(1+Macroindicadores!F$7),AV11))))))))) -> 32.992915 | AX11: =IF(ISBLANK(V11),"",IF(ISBLANK($O11),AJ11,IF($J11="ANUAL",AJ11*(1+Macroindicadores!G$7),IF(AND($I11="NOVO",MONTH($O11)=MONTH(AX$4)),AJ11*(1+Macroindicadores!G$7),IF(AND($J11="PONTUAL",MONTH($O11)=MONTH(AX$4)),AJ11*(1+Macroindicadores!G$7),IF(AND($J11="PONTUAL",MONTH($O11)<MONTH(AX$4)),MIN($AS11:AW11),IF(AND($I11="NOVO",MONTH($O11)>MONTH(AX$4)),AJ11,IF(MONTH($O11)>MONTH(AX$4),AJ11,IF(MONTH($O11)=MONTH(AX$4),AJ11*(1+Macroindicadores!G$7),AW11))))))))) -> 32.992915 | AY11: =IF(ISBLANK(W11),"",IF(ISBLANK($O11),AK11,IF($J11="ANUAL",AK11*(1+Macroindicadores!H$7),IF(AND($I11="NOVO",MONTH($O11)=MONTH(AY$4)),AK11*(1+Macroindicadores!H$7),IF(AND($J11="PONTUAL",MONTH($O11)=MONTH(AY$4)),AK11*(1+Macroindicadores!H$7),IF(AND($J11="PONTUAL",MONTH($O11)<MONTH(AY$4)),MIN($AS11:AX11),IF(AND($I11="NOVO",MONTH($O11)>MONTH(AY$4)),AK11,IF(MONTH($O11)>MONTH(AY$4),AK11,IF(MONTH($O11)=MONTH(AY$4),AK11*(1+Macroindicadores!H$7),AX11))))))))) -> 32.992915 | AZ11: =IF(ISBLANK(X11),"",IF(ISBLANK($O11),AL11,IF($J11="ANUAL",AL11*(1+Macroindicadores!I$7),IF(AND($I11="NOVO",MONTH($O11)=MONTH(AZ$4)),AL11*(1+Macroindicadores!I$7),IF(AND($J11="PONTUAL",MONTH($O11)=MONTH(AZ$4)),AL11*(1+Macroindicadores!I$7),IF(AND($J11="PONTUAL",MONTH($O11)<MONTH(AZ$4)),MIN($AS11:AY11),IF(AND($I11="NOVO",MONTH($O11)>MONTH(AZ$4)),AL11,IF(MONTH($O11)>MONTH(AZ$4),AL11,IF(MONTH($O11)=MONTH(AZ$4),AL11*(1+Macroindicadores!I$7),AY11))))))))) -> 32.992915 | BA11: =IF(ISBLANK(Y11),"",IF(ISBLANK($O11),AM11,IF($J11="ANUAL",AM11*(1+Macroindicadores!J$7),IF(AND($I11="NOVO",MONTH($O11)=MONTH(BA$4)),AM11*(1+Macroindicadores!J$7),IF(AND($J11="PONTUAL",MONTH($O11)=MONTH(BA$4)),AM11*(1+Macroindicadores!J$7),IF(AND($J11="PONTUAL",MONTH($O11)<MONTH(BA$4)),MIN($AS11:AZ11),IF(AND($I11="NOVO",MONTH($O11)>MONTH(BA$4)),AM11,IF(MONTH($O11)>MONTH(BA$4),AM11,IF(MONTH($O11)=MONTH(BA$4),AM11*(1+Macroindicadores!J$7),AZ11))))))))) -> 32.992915 | ... BD11: =IF(ISBLANK(AB11),"",IF(ISBLANK($O11),AP11,IF($J11="ANUAL",AP11*(1+Macroindicadores!M$7),IF(AND($I11="NOVO",MONTH($O11)=MONTH(BD$4)),AP11*(1+Macroindicadores!M$7),IF(AND($J11="PONTUAL",MONTH($O11)=MONTH(BD$4)),AP11*(1+Macroindicadores!M$7),IF(AND($J11="PONTUAL",MONTH($O11)<MONTH(BD$4)),MIN($AS11:BC11),IF(AND($I11="NOVO",MONTH($O11)>MONTH(BD$4)),AP11,IF(MONTH($O11)>MONTH(BD$4),AP11,IF(MONTH($O11)=MONTH(BD$4),AP11*(1+Macroindicadores!M$7),BC11))))))))) -> 32.992915 | BE11: =IF(AND(ISBLANK($Q11),ISBLANK($R11),ISBLANK($S11),ISBLANK($T11),ISBLANK($U11),ISBLANK($V11),ISBLANK($W11),ISBLANK($X11),ISBLANK($Y11),ISBLANK($Z11),ISBLANK($AA11),ISBLANK($AB11)),"",SUM(AS11:BD11)) -> 395.91498 | BG11: =IF(ISBLANK(Q11),"",AS11/Macroindicadores!B$2) -> 5.61104 | BH11: =IF(ISBLANK(R11),"",AT11/Macroindicadores!C$2) -> 5.61104 | BI11: =IF(ISBLANK(S11),"",AU11/Macroindicadores!D$2) -> 5.61104 | BJ11: =IF(ISBLANK(T11),"",AV11/Macroindicadores!E$2) -> 5.61104 | BK11: =IF(ISBLANK(U11),"",AW11/Macroindicadores!F$2) -> 5.61104 | BL11: =IF(ISBLANK(V11),"",AX11/Macroindicadores!G$2) -> 5.61104 | BM11: =IF(ISBLANK(W11),"",AY11/Macroindicadores!H$2) -> 5.61104 | BN11: =IF(ISBLANK(X11),"",AZ11/Macroindicadores!I$2) -> 5.61104 | ... BR11: =IF(ISBLANK(AB11),"",BD11/Macroindicadores!M$2) -> 5.61104 | BS11: =IF(AND(ISBLANK($Q11),ISBLANK($R11),ISBLANK($S11),ISBLANK($T11),ISBLANK($U11),ISBLANK($V11),ISBLANK($W11),ISBLANK($X11),ISBLANK($Y11),ISBLANK($Z11),ISBLANK($AA11),ISBLANK($AB11)),"",SUM(BG11:BR11)) -> 67.33248 | BT11: =IF(ISBLANK($L11),"",_xlfn.XLOOKUP($L11,'CENTRO CUSTO'!$A:$A,'CENTRO CUSTO'!$E:$E,FALSE,0)) -> G&A BU
